00:39:19 - main - WARNING - <module>: 18 - ________________________________HELLO__________________________________
00:41:41 - main - WARNING - <module>: 18 - ________________________________HELLO__________________________________
00:39:26 - main - WARNING - <module>: 18 - ________________________________HELLO__________________________________
00:39:54 - main - WARNING - sending: 194 - A request to the Telegram API was unsuccessful. Error code: 400. Description: Bad Request: PHOTO_INVALID_DIMENSIONS
00:40:21 - main - ERROR - <module>: 234 - A request to the Telegram API was unsuccessful. Error code: 400. Description: Bad Request: PHOTO_INVALID_DIMENSIONS
Traceback (most recent call last):
  File "/home/runner/work/FortDaily-PVE_bot/FortDaily-PVE_bot/main.py", line 191, in sending
    bot.send_photo(chat_id=channel_id, photo=page)
  File "/opt/hostedtoolcache/Python/3.9.17/x64/lib/python3.9/site-packages/telebot/__init__.py", line 1825, in send_photo
    apihelper.send_photo(
  File "/opt/hostedtoolcache/Python/3.9.17/x64/lib/python3.9/site-packages/telebot/apihelper.py", line 494, in send_photo
    return _make_request(token, method_url, params=payload, files=files, method='post')
  File "/opt/hostedtoolcache/Python/3.9.17/x64/lib/python3.9/site-packages/telebot/apihelper.py", line 162, in _make_request
    json_result = _check_result(method_name, result)
  File "/opt/hostedtoolcache/Python/3.9.17/x64/lib/python3.9/site-packages/telebot/apihelper.py", line 189, in _check_result
    raise ApiTelegramException(method_name, result, result_json)
telebot.apihelper.ApiTelegramException: A request to the Telegram API was unsuccessful. Error code: 400. Description: Bad Request: PHOTO_INVALID_DIMENSIONS

During handling of the above exception, another exception occurred:

Traceback (most recent call last):
  File "/home/runner/work/FortDaily-PVE_bot/FortDaily-PVE_bot/main.py", line 232, in <module>
    sending()
  File "/home/runner/work/FortDaily-PVE_bot/FortDaily-PVE_bot/main.py", line 201, in sending
    bot.send_photo(chat_id=channel_id, photo=page)
  File "/opt/hostedtoolcache/Python/3.9.17/x64/lib/python3.9/site-packages/telebot/__init__.py", line 1825, in send_photo
    apihelper.send_photo(
  File "/opt/hostedtoolcache/Python/3.9.17/x64/lib/python3.9/site-packages/telebot/apihelper.py", line 494, in send_photo
    return _make_request(token, method_url, params=payload, files=files, method='post')
  File "/opt/hostedtoolcache/Python/3.9.17/x64/lib/python3.9/site-packages/telebot/apihelper.py", line 162, in _make_request
    json_result = _check_result(method_name, result)
  File "/opt/hostedtoolcache/Python/3.9.17/x64/lib/python3.9/site-packages/telebot/apihelper.py", line 189, in _check_result
    raise ApiTelegramException(method_name, result, result_json)
telebot.apihelper.ApiTelegramException: A request to the Telegram API was unsuccessful. Error code: 400. Description: Bad Request: PHOTO_INVALID_DIMENSIONS
00:41:33 - main - WARNING - <module>: 18 - ________________________________HELLO__________________________________
00:37:55 - main - WARNING - <module>: 18 - ________________________________HELLO__________________________________
00:36:17 - main - WARNING - <module>: 18 - ________________________________HELLO__________________________________
00:36:27 - main - WARNING - <module>: 18 - ________________________________HELLO__________________________________
00:36:27 - main - WARNING - sending: 194 - cannot write empty image as JPEG
00:36:27 - main - ERROR - <module>: 234 - cannot write empty image as JPEG
Traceback (most recent call last):
  File "/home/runner/work/FortDaily-PVE_bot/FortDaily-PVE_bot/main.py", line 191, in sending
    bot.send_photo(chat_id=channel_id, photo=page)
  File "/opt/hostedtoolcache/Python/3.9.17/x64/lib/python3.9/site-packages/telebot/__init__.py", line 1825, in send_photo
    apihelper.send_photo(
  File "/opt/hostedtoolcache/Python/3.9.17/x64/lib/python3.9/site-packages/telebot/apihelper.py", line 469, in send_photo
    files = {'photo': util.pil_image_to_file(photo)}
  File "/opt/hostedtoolcache/Python/3.9.17/x64/lib/python3.9/site-packages/telebot/service_utils.py", line 62, in pil_image_to_file
    image.convert('RGB').save(photoBuffer, extension, quality=quality)
  File "/opt/hostedtoolcache/Python/3.9.17/x64/lib/python3.9/site-packages/PIL/Image.py", line 2432, in save
    save_handler(self, fp, filename)
  File "/opt/hostedtoolcache/Python/3.9.17/x64/lib/python3.9/site-packages/PIL/JpegImagePlugin.py", line 637, in _save
    raise ValueError(msg)
ValueError: cannot write empty image as JPEG

During handling of the above exception, another exception occurred:

Traceback (most recent call last):
  File "/home/runner/work/FortDaily-PVE_bot/FortDaily-PVE_bot/main.py", line 232, in <module>
    sending()
  File "/home/runner/work/FortDaily-PVE_bot/FortDaily-PVE_bot/main.py", line 201, in sending
    bot.send_photo(chat_id=channel_id, photo=page)
  File "/opt/hostedtoolcache/Python/3.9.17/x64/lib/python3.9/site-packages/telebot/__init__.py", line 1825, in send_photo
    apihelper.send_photo(
  File "/opt/hostedtoolcache/Python/3.9.17/x64/lib/python3.9/site-packages/telebot/apihelper.py", line 469, in send_photo
    files = {'photo': util.pil_image_to_file(photo)}
  File "/opt/hostedtoolcache/Python/3.9.17/x64/lib/python3.9/site-packages/telebot/service_utils.py", line 62, in pil_image_to_file
    image.convert('RGB').save(photoBuffer, extension, quality=quality)
  File "/opt/hostedtoolcache/Python/3.9.17/x64/lib/python3.9/site-packages/PIL/Image.py", line 2432, in save
    save_handler(self, fp, filename)
  File "/opt/hostedtoolcache/Python/3.9.17/x64/lib/python3.9/site-packages/PIL/JpegImagePlugin.py", line 637, in _save
    raise ValueError(msg)
ValueError: cannot write empty image as JPEG
00:35:40 - main - WARNING - <module>: 18 - ________________________________HELLO__________________________________
