00:31:37 - main - WARNING - <module>: 18 - ________________________________HELLO__________________________________
00:29:37 - main - WARNING - <module>: 18 - ________________________________HELLO__________________________________
00:31:08 - main - WARNING - <module>: 18 - ________________________________HELLO__________________________________
00:31:17 - main - WARNING - sending: 194 - cannot write empty image as JPEG
00:31:26 - main - ERROR - <module>: 234 - cannot write empty image as JPEG
Traceback (most recent call last):
  File "/home/runner/work/FortDaily-PVE_bot/FortDaily-PVE_bot/main.py", line 187, in sending
    mediagroup = [telebot.types.InputMediaPhoto(i) for i in mediaphoto_jpeg_skins]
  File "/home/runner/work/FortDaily-PVE_bot/FortDaily-PVE_bot/main.py", line 187, in <listcomp>
    mediagroup = [telebot.types.InputMediaPhoto(i) for i in mediaphoto_jpeg_skins]
  File "/opt/hostedtoolcache/Python/3.9.18/x64/lib/python3.9/site-packages/telebot/types.py", line 6222, in __init__
    media = service_utils.pil_image_to_file(media)
  File "/opt/hostedtoolcache/Python/3.9.18/x64/lib/python3.9/site-packages/telebot/service_utils.py", line 62, in pil_image_to_file
    image.convert('RGB').save(photoBuffer, extension, quality=quality)
  File "/opt/hostedtoolcache/Python/3.9.18/x64/lib/python3.9/site-packages/PIL/Image.py", line 2432, in save
    save_handler(self, fp, filename)
  File "/opt/hostedtoolcache/Python/3.9.18/x64/lib/python3.9/site-packages/PIL/JpegImagePlugin.py", line 637, in _save
    raise ValueError(msg)
ValueError: cannot write empty image as JPEG

During handling of the above exception, another exception occurred:

Traceback (most recent call last):
  File "/home/runner/work/FortDaily-PVE_bot/FortDaily-PVE_bot/main.py", line 232, in <module>
    sending()
  File "/home/runner/work/FortDaily-PVE_bot/FortDaily-PVE_bot/main.py", line 197, in sending
    mediagroup = [telebot.types.InputMediaPhoto(i) for i in mediaphoto_jpeg_skins]
  File "/home/runner/work/FortDaily-PVE_bot/FortDaily-PVE_bot/main.py", line 197, in <listcomp>
    mediagroup = [telebot.types.InputMediaPhoto(i) for i in mediaphoto_jpeg_skins]
  File "/opt/hostedtoolcache/Python/3.9.18/x64/lib/python3.9/site-packages/telebot/types.py", line 6222, in __init__
    media = service_utils.pil_image_to_file(media)
  File "/opt/hostedtoolcache/Python/3.9.18/x64/lib/python3.9/site-packages/telebot/service_utils.py", line 62, in pil_image_to_file
    image.convert('RGB').save(photoBuffer, extension, quality=quality)
  File "/opt/hostedtoolcache/Python/3.9.18/x64/lib/python3.9/site-packages/PIL/Image.py", line 2432, in save
    save_handler(self, fp, filename)
  File "/opt/hostedtoolcache/Python/3.9.18/x64/lib/python3.9/site-packages/PIL/JpegImagePlugin.py", line 637, in _save
    raise ValueError(msg)
ValueError: cannot write empty image as JPEG
00:31:17 - main - WARNING - <module>: 18 - ________________________________HELLO__________________________________
00:31:28 - main - WARNING - sending: 194 - cannot write empty image as JPEG
00:31:39 - main - ERROR - <module>: 234 - cannot write empty image as JPEG
Traceback (most recent call last):
  File "/home/runner/work/FortDaily-PVE_bot/FortDaily-PVE_bot/main.py", line 187, in sending
    mediagroup = [telebot.types.InputMediaPhoto(i) for i in mediaphoto_jpeg_skins]
  File "/home/runner/work/FortDaily-PVE_bot/FortDaily-PVE_bot/main.py", line 187, in <listcomp>
    mediagroup = [telebot.types.InputMediaPhoto(i) for i in mediaphoto_jpeg_skins]
  File "/opt/hostedtoolcache/Python/3.9.18/x64/lib/python3.9/site-packages/telebot/types.py", line 6222, in __init__
    media = service_utils.pil_image_to_file(media)
  File "/opt/hostedtoolcache/Python/3.9.18/x64/lib/python3.9/site-packages/telebot/service_utils.py", line 62, in pil_image_to_file
    image.convert('RGB').save(photoBuffer, extension, quality=quality)
  File "/opt/hostedtoolcache/Python/3.9.18/x64/lib/python3.9/site-packages/PIL/Image.py", line 2432, in save
    save_handler(self, fp, filename)
  File "/opt/hostedtoolcache/Python/3.9.18/x64/lib/python3.9/site-packages/PIL/JpegImagePlugin.py", line 637, in _save
    raise ValueError(msg)
ValueError: cannot write empty image as JPEG

During handling of the above exception, another exception occurred:

Traceback (most recent call last):
  File "/home/runner/work/FortDaily-PVE_bot/FortDaily-PVE_bot/main.py", line 232, in <module>
    sending()
  File "/home/runner/work/FortDaily-PVE_bot/FortDaily-PVE_bot/main.py", line 197, in sending
    mediagroup = [telebot.types.InputMediaPhoto(i) for i in mediaphoto_jpeg_skins]
  File "/home/runner/work/FortDaily-PVE_bot/FortDaily-PVE_bot/main.py", line 197, in <listcomp>
    mediagroup = [telebot.types.InputMediaPhoto(i) for i in mediaphoto_jpeg_skins]
  File "/opt/hostedtoolcache/Python/3.9.18/x64/lib/python3.9/site-packages/telebot/types.py", line 6222, in __init__
    media = service_utils.pil_image_to_file(media)
  File "/opt/hostedtoolcache/Python/3.9.18/x64/lib/python3.9/site-packages/telebot/service_utils.py", line 62, in pil_image_to_file
    image.convert('RGB').save(photoBuffer, extension, quality=quality)
  File "/opt/hostedtoolcache/Python/3.9.18/x64/lib/python3.9/site-packages/PIL/Image.py", line 2432, in save
    save_handler(self, fp, filename)
  File "/opt/hostedtoolcache/Python/3.9.18/x64/lib/python3.9/site-packages/PIL/JpegImagePlugin.py", line 637, in _save
    raise ValueError(msg)
ValueError: cannot write empty image as JPEG
00:31:35 - main - WARNING - <module>: 18 - ________________________________HELLO__________________________________
00:31:36 - main - WARNING - sending: 194 - cannot write empty image as JPEG
00:31:36 - main - ERROR - <module>: 234 - cannot write empty image as JPEG
Traceback (most recent call last):
  File "/home/runner/work/FortDaily-PVE_bot/FortDaily-PVE_bot/main.py", line 191, in sending
    bot.send_photo(chat_id=channel_id, photo=page)
  File "/opt/hostedtoolcache/Python/3.9.18/x64/lib/python3.9/site-packages/telebot/__init__.py", line 1825, in send_photo
    apihelper.send_photo(
  File "/opt/hostedtoolcache/Python/3.9.18/x64/lib/python3.9/site-packages/telebot/apihelper.py", line 469, in send_photo
    files = {'photo': util.pil_image_to_file(photo)}
  File "/opt/hostedtoolcache/Python/3.9.18/x64/lib/python3.9/site-packages/telebot/service_utils.py", line 62, in pil_image_to_file
    image.convert('RGB').save(photoBuffer, extension, quality=quality)
  File "/opt/hostedtoolcache/Python/3.9.18/x64/lib/python3.9/site-packages/PIL/Image.py", line 2432, in save
    save_handler(self, fp, filename)
  File "/opt/hostedtoolcache/Python/3.9.18/x64/lib/python3.9/site-packages/PIL/JpegImagePlugin.py", line 637, in _save
    raise ValueError(msg)
ValueError: cannot write empty image as JPEG

During handling of the above exception, another exception occurred:

Traceback (most recent call last):
  File "/home/runner/work/FortDaily-PVE_bot/FortDaily-PVE_bot/main.py", line 232, in <module>
    sending()
  File "/home/runner/work/FortDaily-PVE_bot/FortDaily-PVE_bot/main.py", line 201, in sending
    bot.send_photo(chat_id=channel_id, photo=page)
  File "/opt/hostedtoolcache/Python/3.9.18/x64/lib/python3.9/site-packages/telebot/__init__.py", line 1825, in send_photo
    apihelper.send_photo(
  File "/opt/hostedtoolcache/Python/3.9.18/x64/lib/python3.9/site-packages/telebot/apihelper.py", line 469, in send_photo
    files = {'photo': util.pil_image_to_file(photo)}
  File "/opt/hostedtoolcache/Python/3.9.18/x64/lib/python3.9/site-packages/telebot/service_utils.py", line 62, in pil_image_to_file
    image.convert('RGB').save(photoBuffer, extension, quality=quality)
  File "/opt/hostedtoolcache/Python/3.9.18/x64/lib/python3.9/site-packages/PIL/Image.py", line 2432, in save
    save_handler(self, fp, filename)
  File "/opt/hostedtoolcache/Python/3.9.18/x64/lib/python3.9/site-packages/PIL/JpegImagePlugin.py", line 637, in _save
    raise ValueError(msg)
ValueError: cannot write empty image as JPEG
00:30:04 - main - WARNING - <module>: 18 - ________________________________HELLO__________________________________
00:33:25 - main - WARNING - <module>: 18 - ________________________________HELLO__________________________________
00:31:52 - main - WARNING - <module>: 18 - ________________________________HELLO__________________________________
00:31:50 - main - WARNING - <module>: 18 - ________________________________HELLO__________________________________
00:31:14 - main - WARNING - <module>: 18 - ________________________________HELLO__________________________________
00:31:24 - main - WARNING - <module>: 18 - ________________________________HELLO__________________________________
00:31:34 - main - WARNING - <module>: 18 - ________________________________HELLO__________________________________
00:30:06 - main - WARNING - <module>: 18 - ________________________________HELLO__________________________________
00:33:39 - main - WARNING - <module>: 18 - ________________________________HELLO__________________________________
00:31:57 - main - WARNING - <module>: 18 - ________________________________HELLO__________________________________
00:31:58 - main - WARNING - <module>: 18 - ________________________________HELLO__________________________________
00:32:06 - main - WARNING - <module>: 18 - ________________________________HELLO__________________________________
00:31:38 - main - WARNING - <module>: 18 - ________________________________HELLO__________________________________
00:31:47 - main - WARNING - <module>: 18 - ________________________________HELLO__________________________________
00:30:36 - main - WARNING - <module>: 18 - ________________________________HELLO__________________________________
00:36:43 - main - WARNING - <module>: 18 - ________________________________HELLO__________________________________
00:32:14 - main - WARNING - <module>: 18 - ________________________________HELLO__________________________________
00:32:01 - main - WARNING - <module>: 18 - ________________________________HELLO__________________________________
00:32:25 - main - WARNING - sending: 194 - cannot write empty image as JPEG
00:32:50 - main - ERROR - <module>: 234 - cannot write empty image as JPEG
Traceback (most recent call last):
  File "/home/runner/work/FortDaily-PVE_bot/FortDaily-PVE_bot/main.py", line 191, in sending
    bot.send_photo(chat_id=channel_id, photo=page)
  File "/opt/hostedtoolcache/Python/3.9.18/x64/lib/python3.9/site-packages/telebot/__init__.py", line 1825, in send_photo
    apihelper.send_photo(
  File "/opt/hostedtoolcache/Python/3.9.18/x64/lib/python3.9/site-packages/telebot/apihelper.py", line 469, in send_photo
    files = {'photo': util.pil_image_to_file(photo)}
  File "/opt/hostedtoolcache/Python/3.9.18/x64/lib/python3.9/site-packages/telebot/service_utils.py", line 62, in pil_image_to_file
    image.convert('RGB').save(photoBuffer, extension, quality=quality)
  File "/opt/hostedtoolcache/Python/3.9.18/x64/lib/python3.9/site-packages/PIL/Image.py", line 2432, in save
    save_handler(self, fp, filename)
  File "/opt/hostedtoolcache/Python/3.9.18/x64/lib/python3.9/site-packages/PIL/JpegImagePlugin.py", line 637, in _save
    raise ValueError(msg)
ValueError: cannot write empty image as JPEG

During handling of the above exception, another exception occurred:

Traceback (most recent call last):
  File "/home/runner/work/FortDaily-PVE_bot/FortDaily-PVE_bot/main.py", line 232, in <module>
    sending()
  File "/home/runner/work/FortDaily-PVE_bot/FortDaily-PVE_bot/main.py", line 201, in sending
    bot.send_photo(chat_id=channel_id, photo=page)
  File "/opt/hostedtoolcache/Python/3.9.18/x64/lib/python3.9/site-packages/telebot/__init__.py", line 1825, in send_photo
    apihelper.send_photo(
  File "/opt/hostedtoolcache/Python/3.9.18/x64/lib/python3.9/site-packages/telebot/apihelper.py", line 469, in send_photo
    files = {'photo': util.pil_image_to_file(photo)}
  File "/opt/hostedtoolcache/Python/3.9.18/x64/lib/python3.9/site-packages/telebot/service_utils.py", line 62, in pil_image_to_file
    image.convert('RGB').save(photoBuffer, extension, quality=quality)
  File "/opt/hostedtoolcache/Python/3.9.18/x64/lib/python3.9/site-packages/PIL/Image.py", line 2432, in save
    save_handler(self, fp, filename)
  File "/opt/hostedtoolcache/Python/3.9.18/x64/lib/python3.9/site-packages/PIL/JpegImagePlugin.py", line 637, in _save
    raise ValueError(msg)
ValueError: cannot write empty image as JPEG
00:32:18 - main - WARNING - <module>: 18 - ________________________________HELLO__________________________________
00:32:18 - main - WARNING - sending: 194 - cannot write empty image as JPEG
00:32:18 - main - ERROR - <module>: 234 - cannot write empty image as JPEG
Traceback (most recent call last):
  File "/home/runner/work/FortDaily-PVE_bot/FortDaily-PVE_bot/main.py", line 191, in sending
    bot.send_photo(chat_id=channel_id, photo=page)
  File "/opt/hostedtoolcache/Python/3.9.18/x64/lib/python3.9/site-packages/telebot/__init__.py", line 1825, in send_photo
    apihelper.send_photo(
  File "/opt/hostedtoolcache/Python/3.9.18/x64/lib/python3.9/site-packages/telebot/apihelper.py", line 469, in send_photo
    files = {'photo': util.pil_image_to_file(photo)}
  File "/opt/hostedtoolcache/Python/3.9.18/x64/lib/python3.9/site-packages/telebot/service_utils.py", line 62, in pil_image_to_file
    image.convert('RGB').save(photoBuffer, extension, quality=quality)
  File "/opt/hostedtoolcache/Python/3.9.18/x64/lib/python3.9/site-packages/PIL/Image.py", line 2432, in save
    save_handler(self, fp, filename)
  File "/opt/hostedtoolcache/Python/3.9.18/x64/lib/python3.9/site-packages/PIL/JpegImagePlugin.py", line 637, in _save
    raise ValueError(msg)
ValueError: cannot write empty image as JPEG

During handling of the above exception, another exception occurred:

Traceback (most recent call last):
  File "/home/runner/work/FortDaily-PVE_bot/FortDaily-PVE_bot/main.py", line 232, in <module>
    sending()
  File "/home/runner/work/FortDaily-PVE_bot/FortDaily-PVE_bot/main.py", line 201, in sending
    bot.send_photo(chat_id=channel_id, photo=page)
  File "/opt/hostedtoolcache/Python/3.9.18/x64/lib/python3.9/site-packages/telebot/__init__.py", line 1825, in send_photo
    apihelper.send_photo(
  File "/opt/hostedtoolcache/Python/3.9.18/x64/lib/python3.9/site-packages/telebot/apihelper.py", line 469, in send_photo
    files = {'photo': util.pil_image_to_file(photo)}
  File "/opt/hostedtoolcache/Python/3.9.18/x64/lib/python3.9/site-packages/telebot/service_utils.py", line 62, in pil_image_to_file
    image.convert('RGB').save(photoBuffer, extension, quality=quality)
  File "/opt/hostedtoolcache/Python/3.9.18/x64/lib/python3.9/site-packages/PIL/Image.py", line 2432, in save
    save_handler(self, fp, filename)
  File "/opt/hostedtoolcache/Python/3.9.18/x64/lib/python3.9/site-packages/PIL/JpegImagePlugin.py", line 637, in _save
    raise ValueError(msg)
ValueError: cannot write empty image as JPEG
00:31:47 - main - WARNING - <module>: 18 - ________________________________HELLO__________________________________
00:31:49 - main - WARNING - <module>: 18 - ________________________________HELLO__________________________________
00:31:16 - main - WARNING - <module>: 18 - ________________________________HELLO__________________________________
00:31:16 - main - WARNING - sending: 194 - cannot write empty image as JPEG
00:31:16 - main - ERROR - <module>: 234 - cannot write empty image as JPEG
Traceback (most recent call last):
  File "/home/runner/work/FortDaily-PVE_bot/FortDaily-PVE_bot/main.py", line 191, in sending
    bot.send_photo(chat_id=channel_id, photo=page)
  File "/opt/hostedtoolcache/Python/3.9.18/x64/lib/python3.9/site-packages/telebot/__init__.py", line 1825, in send_photo
    apihelper.send_photo(
  File "/opt/hostedtoolcache/Python/3.9.18/x64/lib/python3.9/site-packages/telebot/apihelper.py", line 469, in send_photo
    files = {'photo': util.pil_image_to_file(photo)}
  File "/opt/hostedtoolcache/Python/3.9.18/x64/lib/python3.9/site-packages/telebot/service_utils.py", line 62, in pil_image_to_file
    image.convert('RGB').save(photoBuffer, extension, quality=quality)
  File "/opt/hostedtoolcache/Python/3.9.18/x64/lib/python3.9/site-packages/PIL/Image.py", line 2432, in save
    save_handler(self, fp, filename)
  File "/opt/hostedtoolcache/Python/3.9.18/x64/lib/python3.9/site-packages/PIL/JpegImagePlugin.py", line 637, in _save
    raise ValueError(msg)
ValueError: cannot write empty image as JPEG

During handling of the above exception, another exception occurred:

Traceback (most recent call last):
  File "/home/runner/work/FortDaily-PVE_bot/FortDaily-PVE_bot/main.py", line 232, in <module>
    sending()
  File "/home/runner/work/FortDaily-PVE_bot/FortDaily-PVE_bot/main.py", line 201, in sending
    bot.send_photo(chat_id=channel_id, photo=page)
  File "/opt/hostedtoolcache/Python/3.9.18/x64/lib/python3.9/site-packages/telebot/__init__.py", line 1825, in send_photo
    apihelper.send_photo(
  File "/opt/hostedtoolcache/Python/3.9.18/x64/lib/python3.9/site-packages/telebot/apihelper.py", line 469, in send_photo
    files = {'photo': util.pil_image_to_file(photo)}
  File "/opt/hostedtoolcache/Python/3.9.18/x64/lib/python3.9/site-packages/telebot/service_utils.py", line 62, in pil_image_to_file
    image.convert('RGB').save(photoBuffer, extension, quality=quality)
  File "/opt/hostedtoolcache/Python/3.9.18/x64/lib/python3.9/site-packages/PIL/Image.py", line 2432, in save
    save_handler(self, fp, filename)
  File "/opt/hostedtoolcache/Python/3.9.18/x64/lib/python3.9/site-packages/PIL/JpegImagePlugin.py", line 637, in _save
    raise ValueError(msg)
ValueError: cannot write empty image as JPEG
00:34:12 - main - WARNING - <module>: 18 - ________________________________HELLO__________________________________
00:32:19 - main - WARNING - <module>: 18 - ________________________________HELLO__________________________________
00:31:43 - main - WARNING - <module>: 18 - ________________________________HELLO__________________________________
00:31:35 - main - WARNING - <module>: 18 - ________________________________HELLO__________________________________
00:30:01 - main - WARNING - <module>: 18 - ________________________________HELLO__________________________________
00:32:49 - main - WARNING - <module>: 18 - ________________________________HELLO__________________________________
00:30:44 - main - WARNING - <module>: 18 - ________________________________HELLO__________________________________
00:34:33 - main - WARNING - <module>: 18 - ________________________________HELLO__________________________________
00:32:48 - main - WARNING - <module>: 18 - ________________________________HELLO__________________________________
00:32:14 - main - WARNING - <module>: 18 - ________________________________HELLO__________________________________
00:32:01 - main - WARNING - <module>: 18 - ________________________________HELLO__________________________________
00:31:50 - main - WARNING - <module>: 18 - ________________________________HELLO__________________________________
00:31:55 - main - WARNING - <module>: 18 - ________________________________HELLO__________________________________
00:30:47 - main - WARNING - <module>: 18 - ________________________________HELLO__________________________________
00:34:29 - main - WARNING - <module>: 18 - ________________________________HELLO__________________________________
00:32:12 - main - WARNING - <module>: 18 - ________________________________HELLO__________________________________
00:31:58 - main - WARNING - <module>: 18 - ________________________________HELLO__________________________________
00:31:42 - main - WARNING - <module>: 18 - ________________________________HELLO__________________________________
00:31:04 - main - WARNING - <module>: 18 - ________________________________HELLO__________________________________
00:31:18 - main - WARNING - <module>: 18 - ________________________________HELLO__________________________________
00:30:37 - main - WARNING - <module>: 18 - ________________________________HELLO__________________________________
00:34:04 - main - WARNING - <module>: 18 - ________________________________HELLO__________________________________
00:34:23 - main - WARNING - sending: 194 - A request to the Telegram API was unsuccessful. Error code: 400. Description: Bad Request: failed to send message #7 with the error message "PHOTO_INVALID_DIMENSIONS"
00:34:42 - main - ERROR - <module>: 234 - A request to the Telegram API was unsuccessful. Error code: 400. Description: Bad Request: failed to send message #8 with the error message "PHOTO_INVALID_DIMENSIONS"
Traceback (most recent call last):
  File "/home/runner/work/FortDaily-PVE_bot/FortDaily-PVE_bot/main.py", line 188, in sending
    bot.send_media_group(chat_id=channel_id, media=mediagroup)
  File "/opt/hostedtoolcache/Python/3.9.18/x64/lib/python3.9/site-packages/telebot/__init__.py", line 2523, in send_media_group
    result = apihelper.send_media_group(
  File "/opt/hostedtoolcache/Python/3.9.18/x64/lib/python3.9/site-packages/telebot/apihelper.py", line 516, in send_media_group
    return _make_request(
  File "/opt/hostedtoolcache/Python/3.9.18/x64/lib/python3.9/site-packages/telebot/apihelper.py", line 162, in _make_request
    json_result = _check_result(method_name, result)
  File "/opt/hostedtoolcache/Python/3.9.18/x64/lib/python3.9/site-packages/telebot/apihelper.py", line 189, in _check_result
    raise ApiTelegramException(method_name, result, result_json)
telebot.apihelper.ApiTelegramException: A request to the Telegram API was unsuccessful. Error code: 400. Description: Bad Request: failed to send message #7 with the error message "PHOTO_INVALID_DIMENSIONS"

During handling of the above exception, another exception occurred:

Traceback (most recent call last):
  File "/home/runner/work/FortDaily-PVE_bot/FortDaily-PVE_bot/main.py", line 232, in <module>
    sending()
  File "/home/runner/work/FortDaily-PVE_bot/FortDaily-PVE_bot/main.py", line 198, in sending
    bot.send_media_group(chat_id=channel_id, media=mediagroup)
  File "/opt/hostedtoolcache/Python/3.9.18/x64/lib/python3.9/site-packages/telebot/__init__.py", line 2523, in send_media_group
    result = apihelper.send_media_group(
  File "/opt/hostedtoolcache/Python/3.9.18/x64/lib/python3.9/site-packages/telebot/apihelper.py", line 516, in send_media_group
    return _make_request(
  File "/opt/hostedtoolcache/Python/3.9.18/x64/lib/python3.9/site-packages/telebot/apihelper.py", line 162, in _make_request
    json_result = _check_result(method_name, result)
  File "/opt/hostedtoolcache/Python/3.9.18/x64/lib/python3.9/site-packages/telebot/apihelper.py", line 189, in _check_result
    raise ApiTelegramException(method_name, result, result_json)
telebot.apihelper.ApiTelegramException: A request to the Telegram API was unsuccessful. Error code: 400. Description: Bad Request: failed to send message #8 with the error message "PHOTO_INVALID_DIMENSIONS"
00:32:18 - main - WARNING - <module>: 18 - ________________________________HELLO__________________________________
00:32:45 - main - WARNING - sending: 194 - A request to the Telegram API was unsuccessful. Error code: 400. Description: Bad Request: failed to send message #7 with the error message "PHOTO_INVALID_DIMENSIONS"
00:33:12 - main - ERROR - <module>: 234 - A request to the Telegram API was unsuccessful. Error code: 400. Description: Bad Request: failed to send message #7 with the error message "PHOTO_INVALID_DIMENSIONS"
Traceback (most recent call last):
  File "/home/runner/work/FortDaily-PVE_bot/FortDaily-PVE_bot/main.py", line 188, in sending
    bot.send_media_group(chat_id=channel_id, media=mediagroup)
  File "/opt/hostedtoolcache/Python/3.9.18/x64/lib/python3.9/site-packages/telebot/__init__.py", line 2523, in send_media_group
    result = apihelper.send_media_group(
  File "/opt/hostedtoolcache/Python/3.9.18/x64/lib/python3.9/site-packages/telebot/apihelper.py", line 516, in send_media_group
    return _make_request(
  File "/opt/hostedtoolcache/Python/3.9.18/x64/lib/python3.9/site-packages/telebot/apihelper.py", line 162, in _make_request
    json_result = _check_result(method_name, result)
  File "/opt/hostedtoolcache/Python/3.9.18/x64/lib/python3.9/site-packages/telebot/apihelper.py", line 189, in _check_result
    raise ApiTelegramException(method_name, result, result_json)
telebot.apihelper.ApiTelegramException: A request to the Telegram API was unsuccessful. Error code: 400. Description: Bad Request: failed to send message #7 with the error message "PHOTO_INVALID_DIMENSIONS"

During handling of the above exception, another exception occurred:

Traceback (most recent call last):
  File "/home/runner/work/FortDaily-PVE_bot/FortDaily-PVE_bot/main.py", line 232, in <module>
    sending()
  File "/home/runner/work/FortDaily-PVE_bot/FortDaily-PVE_bot/main.py", line 198, in sending
    bot.send_media_group(chat_id=channel_id, media=mediagroup)
  File "/opt/hostedtoolcache/Python/3.9.18/x64/lib/python3.9/site-packages/telebot/__init__.py", line 2523, in send_media_group
    result = apihelper.send_media_group(
  File "/opt/hostedtoolcache/Python/3.9.18/x64/lib/python3.9/site-packages/telebot/apihelper.py", line 516, in send_media_group
    return _make_request(
  File "/opt/hostedtoolcache/Python/3.9.18/x64/lib/python3.9/site-packages/telebot/apihelper.py", line 162, in _make_request
    json_result = _check_result(method_name, result)
  File "/opt/hostedtoolcache/Python/3.9.18/x64/lib/python3.9/site-packages/telebot/apihelper.py", line 189, in _check_result
    raise ApiTelegramException(method_name, result, result_json)
telebot.apihelper.ApiTelegramException: A request to the Telegram API was unsuccessful. Error code: 400. Description: Bad Request: failed to send message #7 with the error message "PHOTO_INVALID_DIMENSIONS"
00:32:12 - main - WARNING - <module>: 18 - ________________________________HELLO__________________________________
00:32:35 - main - WARNING - sending: 194 - A request to the Telegram API was unsuccessful. Error code: 400. Description: Bad Request: failed to send message #7 with the error message "PHOTO_INVALID_DIMENSIONS"
00:32:57 - main - ERROR - <module>: 234 - A request to the Telegram API was unsuccessful. Error code: 400. Description: Bad Request: failed to send message #8 with the error message "PHOTO_INVALID_DIMENSIONS"
Traceback (most recent call last):
  File "/home/runner/work/FortDaily-PVE_bot/FortDaily-PVE_bot/main.py", line 188, in sending
    bot.send_media_group(chat_id=channel_id, media=mediagroup)
  File "/opt/hostedtoolcache/Python/3.9.18/x64/lib/python3.9/site-packages/telebot/__init__.py", line 2523, in send_media_group
    result = apihelper.send_media_group(
  File "/opt/hostedtoolcache/Python/3.9.18/x64/lib/python3.9/site-packages/telebot/apihelper.py", line 516, in send_media_group
    return _make_request(
  File "/opt/hostedtoolcache/Python/3.9.18/x64/lib/python3.9/site-packages/telebot/apihelper.py", line 162, in _make_request
    json_result = _check_result(method_name, result)
  File "/opt/hostedtoolcache/Python/3.9.18/x64/lib/python3.9/site-packages/telebot/apihelper.py", line 189, in _check_result
    raise ApiTelegramException(method_name, result, result_json)
telebot.apihelper.ApiTelegramException: A request to the Telegram API was unsuccessful. Error code: 400. Description: Bad Request: failed to send message #7 with the error message "PHOTO_INVALID_DIMENSIONS"

During handling of the above exception, another exception occurred:

Traceback (most recent call last):
  File "/home/runner/work/FortDaily-PVE_bot/FortDaily-PVE_bot/main.py", line 232, in <module>
    sending()
  File "/home/runner/work/FortDaily-PVE_bot/FortDaily-PVE_bot/main.py", line 198, in sending
    bot.send_media_group(chat_id=channel_id, media=mediagroup)
  File "/opt/hostedtoolcache/Python/3.9.18/x64/lib/python3.9/site-packages/telebot/__init__.py", line 2523, in send_media_group
    result = apihelper.send_media_group(
  File "/opt/hostedtoolcache/Python/3.9.18/x64/lib/python3.9/site-packages/telebot/apihelper.py", line 516, in send_media_group
    return _make_request(
  File "/opt/hostedtoolcache/Python/3.9.18/x64/lib/python3.9/site-packages/telebot/apihelper.py", line 162, in _make_request
    json_result = _check_result(method_name, result)
  File "/opt/hostedtoolcache/Python/3.9.18/x64/lib/python3.9/site-packages/telebot/apihelper.py", line 189, in _check_result
    raise ApiTelegramException(method_name, result, result_json)
telebot.apihelper.ApiTelegramException: A request to the Telegram API was unsuccessful. Error code: 400. Description: Bad Request: failed to send message #8 with the error message "PHOTO_INVALID_DIMENSIONS"
00:34:25 - main - WARNING - <module>: 18 - ________________________________HELLO__________________________________
00:34:49 - main - WARNING - sending: 194 - A request to the Telegram API was unsuccessful. Error code: 400. Description: Bad Request: failed to send message #6 with the error message "PHOTO_INVALID_DIMENSIONS"
00:35:13 - main - ERROR - <module>: 234 - A request to the Telegram API was unsuccessful. Error code: 400. Description: Bad Request: failed to send message #6 with the error message "PHOTO_INVALID_DIMENSIONS"
Traceback (most recent call last):
  File "/home/runner/work/FortDaily-PVE_bot/FortDaily-PVE_bot/main.py", line 188, in sending
    bot.send_media_group(chat_id=channel_id, media=mediagroup)
  File "/opt/hostedtoolcache/Python/3.9.18/x64/lib/python3.9/site-packages/telebot/__init__.py", line 2523, in send_media_group
    result = apihelper.send_media_group(
  File "/opt/hostedtoolcache/Python/3.9.18/x64/lib/python3.9/site-packages/telebot/apihelper.py", line 516, in send_media_group
    return _make_request(
  File "/opt/hostedtoolcache/Python/3.9.18/x64/lib/python3.9/site-packages/telebot/apihelper.py", line 162, in _make_request
    json_result = _check_result(method_name, result)
  File "/opt/hostedtoolcache/Python/3.9.18/x64/lib/python3.9/site-packages/telebot/apihelper.py", line 189, in _check_result
    raise ApiTelegramException(method_name, result, result_json)
telebot.apihelper.ApiTelegramException: A request to the Telegram API was unsuccessful. Error code: 400. Description: Bad Request: failed to send message #6 with the error message "PHOTO_INVALID_DIMENSIONS"

During handling of the above exception, another exception occurred:

Traceback (most recent call last):
  File "/home/runner/work/FortDaily-PVE_bot/FortDaily-PVE_bot/main.py", line 232, in <module>
    sending()
  File "/home/runner/work/FortDaily-PVE_bot/FortDaily-PVE_bot/main.py", line 198, in sending
    bot.send_media_group(chat_id=channel_id, media=mediagroup)
  File "/opt/hostedtoolcache/Python/3.9.18/x64/lib/python3.9/site-packages/telebot/__init__.py", line 2523, in send_media_group
    result = apihelper.send_media_group(
  File "/opt/hostedtoolcache/Python/3.9.18/x64/lib/python3.9/site-packages/telebot/apihelper.py", line 516, in send_media_group
    return _make_request(
  File "/opt/hostedtoolcache/Python/3.9.18/x64/lib/python3.9/site-packages/telebot/apihelper.py", line 162, in _make_request
    json_result = _check_result(method_name, result)
  File "/opt/hostedtoolcache/Python/3.9.18/x64/lib/python3.9/site-packages/telebot/apihelper.py", line 189, in _check_result
    raise ApiTelegramException(method_name, result, result_json)
telebot.apihelper.ApiTelegramException: A request to the Telegram API was unsuccessful. Error code: 400. Description: Bad Request: failed to send message #6 with the error message "PHOTO_INVALID_DIMENSIONS"
