
00:33:23 - main - WARNING - <module>: 18 - ________________________________HELLO__________________________________
00:33:57 - main - WARNING - <module>: 18 - ________________________________HELLO__________________________________
00:33:45 - main - WARNING - <module>: 18 - ________________________________HELLO__________________________________
00:32:51 - main - WARNING - <module>: 18 - ________________________________HELLO__________________________________
00:36:32 - main - WARNING - <module>: 18 - ________________________________HELLO__________________________________
00:36:32 - main - WARNING - sending: 196 - cannot write empty image as JPEG
00:36:33 - main - ERROR - <module>: 239 - cannot write empty image as JPEG
Traceback (most recent call last):
  File "/home/runner/work/FortDaily-PVE_bot/FortDaily-PVE_bot/main.py", line 192, in sending
    bot.send_photo(chat_id=channel_id, photo=page)
  File "/opt/hostedtoolcache/Python/3.9.18/x64/lib/python3.9/site-packages/telebot/__init__.py", line 1825, in send_photo
    apihelper.send_photo(
  File "/opt/hostedtoolcache/Python/3.9.18/x64/lib/python3.9/site-packages/telebot/apihelper.py", line 469, in send_photo
    files = {'photo': util.pil_image_to_file(photo)}
  File "/opt/hostedtoolcache/Python/3.9.18/x64/lib/python3.9/site-packages/telebot/service_utils.py", line 62, in pil_image_to_file
    image.convert('RGB').save(photoBuffer, extension, quality=quality)
  File "/opt/hostedtoolcache/Python/3.9.18/x64/lib/python3.9/site-packages/PIL/Image.py", line 2432, in save
    save_handler(self, fp, filename)
  File "/opt/hostedtoolcache/Python/3.9.18/x64/lib/python3.9/site-packages/PIL/JpegImagePlugin.py", line 637, in _save
    raise ValueError(msg)
ValueError: cannot write empty image as JPEG

During handling of the above exception, another exception occurred:

Traceback (most recent call last):
  File "/home/runner/work/FortDaily-PVE_bot/FortDaily-PVE_bot/main.py", line 237, in <module>
    sending()
  File "/home/runner/work/FortDaily-PVE_bot/FortDaily-PVE_bot/main.py", line 205, in sending
    bot.send_photo(chat_id=channel_id, photo=page)
  File "/opt/hostedtoolcache/Python/3.9.18/x64/lib/python3.9/site-packages/telebot/__init__.py", line 1825, in send_photo
    apihelper.send_photo(
  File "/opt/hostedtoolcache/Python/3.9.18/x64/lib/python3.9/site-packages/telebot/apihelper.py", line 469, in send_photo
    files = {'photo': util.pil_image_to_file(photo)}
  File "/opt/hostedtoolcache/Python/3.9.18/x64/lib/python3.9/site-packages/telebot/service_utils.py", line 62, in pil_image_to_file
    image.convert('RGB').save(photoBuffer, extension, quality=quality)
  File "/opt/hostedtoolcache/Python/3.9.18/x64/lib/python3.9/site-packages/PIL/Image.py", line 2432, in save
    save_handler(self, fp, filename)
  File "/opt/hostedtoolcache/Python/3.9.18/x64/lib/python3.9/site-packages/PIL/JpegImagePlugin.py", line 637, in _save
    raise ValueError(msg)
ValueError: cannot write empty image as JPEG
00:34:40 - main - WARNING - <module>: 18 - ________________________________HELLO__________________________________
00:34:44 - main - WARNING - sending: 196 - cannot write empty image as JPEG
00:34:49 - main - ERROR - <module>: 239 - cannot write empty image as JPEG
Traceback (most recent call last):
  File "/home/runner/work/FortDaily-PVE_bot/FortDaily-PVE_bot/main.py", line 188, in sending
    mediagroup = [telebot.types.InputMediaPhoto(i) for i in mediaphoto_jpeg_skins]
  File "/home/runner/work/FortDaily-PVE_bot/FortDaily-PVE_bot/main.py", line 188, in <listcomp>
    mediagroup = [telebot.types.InputMediaPhoto(i) for i in mediaphoto_jpeg_skins]
  File "/opt/hostedtoolcache/Python/3.9.18/x64/lib/python3.9/site-packages/telebot/types.py", line 6222, in __init__
    media = service_utils.pil_image_to_file(media)
  File "/opt/hostedtoolcache/Python/3.9.18/x64/lib/python3.9/site-packages/telebot/service_utils.py", line 62, in pil_image_to_file
    image.convert('RGB').save(photoBuffer, extension, quality=quality)
  File "/opt/hostedtoolcache/Python/3.9.18/x64/lib/python3.9/site-packages/PIL/Image.py", line 2432, in save
    save_handler(self, fp, filename)
  File "/opt/hostedtoolcache/Python/3.9.18/x64/lib/python3.9/site-packages/PIL/JpegImagePlugin.py", line 637, in _save
    raise ValueError(msg)
ValueError: cannot write empty image as JPEG

During handling of the above exception, another exception occurred:

Traceback (most recent call last):
  File "/home/runner/work/FortDaily-PVE_bot/FortDaily-PVE_bot/main.py", line 237, in <module>
    sending()
  File "/home/runner/work/FortDaily-PVE_bot/FortDaily-PVE_bot/main.py", line 201, in sending
    mediagroup = [telebot.types.InputMediaPhoto(i) for i in mediaphoto_jpeg_skins]
  File "/home/runner/work/FortDaily-PVE_bot/FortDaily-PVE_bot/main.py", line 201, in <listcomp>
    mediagroup = [telebot.types.InputMediaPhoto(i) for i in mediaphoto_jpeg_skins]
  File "/opt/hostedtoolcache/Python/3.9.18/x64/lib/python3.9/site-packages/telebot/types.py", line 6222, in __init__
    media = service_utils.pil_image_to_file(media)
  File "/opt/hostedtoolcache/Python/3.9.18/x64/lib/python3.9/site-packages/telebot/service_utils.py", line 62, in pil_image_to_file
    image.convert('RGB').save(photoBuffer, extension, quality=quality)
  File "/opt/hostedtoolcache/Python/3.9.18/x64/lib/python3.9/site-packages/PIL/Image.py", line 2432, in save
    save_handler(self, fp, filename)
  File "/opt/hostedtoolcache/Python/3.9.18/x64/lib/python3.9/site-packages/PIL/JpegImagePlugin.py", line 637, in _save
    raise ValueError(msg)
ValueError: cannot write empty image as JPEG
14:47:58 - main - WARNING - <module>: 18 - ________________________________HELLO__________________________________
00:34:37 - main - WARNING - <module>: 18 - ________________________________HELLO__________________________________
00:35:37 - main - WARNING - <module>: 18 - ________________________________HELLO__________________________________
00:33:59 - main - WARNING - <module>: 18 - ________________________________HELLO__________________________________
00:32:46 - main - WARNING - <module>: 18 - ________________________________HELLO__________________________________
00:32:55 - main - WARNING - sending: 197 - cannot write empty image as JPEG
00:32:01 - main - WARNING - <module>: 18 - ________________________________HELLO__________________________________
00:32:11 - main - WARNING - sending: 197 - cannot write empty image as JPEG
00:36:20 - main - WARNING - <module>: 18 - ________________________________HELLO__________________________________
00:36:28 - main - WARNING - sending: 197 - cannot write empty image as JPEG
00:34:21 - main - WARNING - <module>: 18 - ________________________________HELLO__________________________________
00:34:30 - main - WARNING - sending: 197 - cannot write empty image as JPEG
00:34:26 - main - WARNING - <module>: 18 - ________________________________HELLO__________________________________
00:34:28 - main - WARNING - sending: 197 - cannot write empty image as JPEG
00:34:57 - main - WARNING - <module>: 18 - ________________________________HELLO__________________________________
00:35:05 - main - WARNING - sending: 197 - cannot write empty image as JPEG
00:34:06 - main - WARNING - <module>: 18 - ________________________________HELLO__________________________________
00:34:13 - main - WARNING - sending: 197 - cannot write empty image as JPEG
00:37:28 - main - WARNING - <module>: 18 - ________________________________HELLO__________________________________
00:32:53 - main - WARNING - <module>: 18 - ________________________________HELLO__________________________________
00:36:23 - main - WARNING - <module>: 18 - ________________________________HELLO__________________________________
00:36:23 - main - WARNING - sending: 197 - cannot write empty image as JPEG
00:36:24 - main - ERROR - <module>: 240 - A request to the Telegram API was unsuccessful. Error code: 400. Description: Bad Request: there are no messages to send
Traceback (most recent call last):
  File "/home/runner/work/FortDaily-PVE_bot/FortDaily-PVE_bot/main.py", line 189, in sending
    mediagroup = [telebot.types.InputMediaPhoto(i) for i in mediaphoto_jpeg_skins]
  File "/home/runner/work/FortDaily-PVE_bot/FortDaily-PVE_bot/main.py", line 189, in <listcomp>
    mediagroup = [telebot.types.InputMediaPhoto(i) for i in mediaphoto_jpeg_skins]
  File "/opt/hostedtoolcache/Python/3.9.18/x64/lib/python3.9/site-packages/telebot/types.py", line 6222, in __init__
    media = service_utils.pil_image_to_file(media)
  File "/opt/hostedtoolcache/Python/3.9.18/x64/lib/python3.9/site-packages/telebot/service_utils.py", line 62, in pil_image_to_file
    image.convert('RGB').save(photoBuffer, extension, quality=quality)
  File "/opt/hostedtoolcache/Python/3.9.18/x64/lib/python3.9/site-packages/PIL/Image.py", line 2432, in save
    save_handler(self, fp, filename)
  File "/opt/hostedtoolcache/Python/3.9.18/x64/lib/python3.9/site-packages/PIL/JpegImagePlugin.py", line 637, in _save
    raise ValueError(msg)
ValueError: cannot write empty image as JPEG

During handling of the above exception, another exception occurred:

Traceback (most recent call last):
  File "/home/runner/work/FortDaily-PVE_bot/FortDaily-PVE_bot/main.py", line 238, in <module>
    sending()
  File "/home/runner/work/FortDaily-PVE_bot/FortDaily-PVE_bot/main.py", line 203, in sending
    bot.send_media_group(chat_id=channel_id, media=mediagroup)
  File "/opt/hostedtoolcache/Python/3.9.18/x64/lib/python3.9/site-packages/telebot/__init__.py", line 2523, in send_media_group
    result = apihelper.send_media_group(
  File "/opt/hostedtoolcache/Python/3.9.18/x64/lib/python3.9/site-packages/telebot/apihelper.py", line 516, in send_media_group
    return _make_request(
  File "/opt/hostedtoolcache/Python/3.9.18/x64/lib/python3.9/site-packages/telebot/apihelper.py", line 162, in _make_request
    json_result = _check_result(method_name, result)
  File "/opt/hostedtoolcache/Python/3.9.18/x64/lib/python3.9/site-packages/telebot/apihelper.py", line 189, in _check_result
    raise ApiTelegramException(method_name, result, result_json)
telebot.apihelper.ApiTelegramException: A request to the Telegram API was unsuccessful. Error code: 400. Description: Bad Request: there are no messages to send
00:34:56 - main - WARNING - <module>: 18 - ________________________________HELLO__________________________________
00:34:56 - main - WARNING - sending: 197 - cannot write empty image as JPEG
00:34:58 - main - ERROR - <module>: 240 - cannot write empty image as JPEG
Traceback (most recent call last):
  File "/home/runner/work/FortDaily-PVE_bot/FortDaily-PVE_bot/main.py", line 193, in sending
    bot.send_photo(chat_id=channel_id, photo=page)
  File "/opt/hostedtoolcache/Python/3.9.18/x64/lib/python3.9/site-packages/telebot/__init__.py", line 1825, in send_photo
    apihelper.send_photo(
  File "/opt/hostedtoolcache/Python/3.9.18/x64/lib/python3.9/site-packages/telebot/apihelper.py", line 469, in send_photo
    files = {'photo': util.pil_image_to_file(photo)}
  File "/opt/hostedtoolcache/Python/3.9.18/x64/lib/python3.9/site-packages/telebot/service_utils.py", line 62, in pil_image_to_file
    image.convert('RGB').save(photoBuffer, extension, quality=quality)
  File "/opt/hostedtoolcache/Python/3.9.18/x64/lib/python3.9/site-packages/PIL/Image.py", line 2432, in save
    save_handler(self, fp, filename)
  File "/opt/hostedtoolcache/Python/3.9.18/x64/lib/python3.9/site-packages/PIL/JpegImagePlugin.py", line 637, in _save
    raise ValueError(msg)
ValueError: cannot write empty image as JPEG

During handling of the above exception, another exception occurred:

Traceback (most recent call last):
  File "/home/runner/work/FortDaily-PVE_bot/FortDaily-PVE_bot/main.py", line 238, in <module>
    sending()
  File "/home/runner/work/FortDaily-PVE_bot/FortDaily-PVE_bot/main.py", line 206, in sending
    bot.send_photo(chat_id=channel_id, photo=page)
  File "/opt/hostedtoolcache/Python/3.9.18/x64/lib/python3.9/site-packages/telebot/__init__.py", line 1825, in send_photo
    apihelper.send_photo(
  File "/opt/hostedtoolcache/Python/3.9.18/x64/lib/python3.9/site-packages/telebot/apihelper.py", line 469, in send_photo
    files = {'photo': util.pil_image_to_file(photo)}
  File "/opt/hostedtoolcache/Python/3.9.18/x64/lib/python3.9/site-packages/telebot/service_utils.py", line 62, in pil_image_to_file
    image.convert('RGB').save(photoBuffer, extension, quality=quality)
  File "/opt/hostedtoolcache/Python/3.9.18/x64/lib/python3.9/site-packages/PIL/Image.py", line 2432, in save
    save_handler(self, fp, filename)
  File "/opt/hostedtoolcache/Python/3.9.18/x64/lib/python3.9/site-packages/PIL/JpegImagePlugin.py", line 637, in _save
    raise ValueError(msg)
ValueError: cannot write empty image as JPEG
00:34:48 - main - WARNING - <module>: 18 - ________________________________HELLO__________________________________
00:35:29 - main - WARNING - sending: 197 - cannot write empty image as JPEG
00:35:59 - main - ERROR - <module>: 240 - A request to the Telegram API was unsuccessful. Error code: 429. Description: Too Many Requests: retry after 14
Traceback (most recent call last):
  File "/home/runner/work/FortDaily-PVE_bot/FortDaily-PVE_bot/main.py", line 193, in sending
    bot.send_photo(chat_id=channel_id, photo=page)
  File "/opt/hostedtoolcache/Python/3.9.18/x64/lib/python3.9/site-packages/telebot/__init__.py", line 1825, in send_photo
    apihelper.send_photo(
  File "/opt/hostedtoolcache/Python/3.9.18/x64/lib/python3.9/site-packages/telebot/apihelper.py", line 469, in send_photo
    files = {'photo': util.pil_image_to_file(photo)}
  File "/opt/hostedtoolcache/Python/3.9.18/x64/lib/python3.9/site-packages/telebot/service_utils.py", line 62, in pil_image_to_file
    image.convert('RGB').save(photoBuffer, extension, quality=quality)
  File "/opt/hostedtoolcache/Python/3.9.18/x64/lib/python3.9/site-packages/PIL/Image.py", line 2432, in save
    save_handler(self, fp, filename)
  File "/opt/hostedtoolcache/Python/3.9.18/x64/lib/python3.9/site-packages/PIL/JpegImagePlugin.py", line 637, in _save
    raise ValueError(msg)
ValueError: cannot write empty image as JPEG

During handling of the above exception, another exception occurred:

Traceback (most recent call last):
  File "/home/runner/work/FortDaily-PVE_bot/FortDaily-PVE_bot/main.py", line 206, in sending
    bot.send_photo(chat_id=channel_id, photo=page)
  File "/opt/hostedtoolcache/Python/3.9.18/x64/lib/python3.9/site-packages/telebot/__init__.py", line 1825, in send_photo
    apihelper.send_photo(
  File "/opt/hostedtoolcache/Python/3.9.18/x64/lib/python3.9/site-packages/telebot/apihelper.py", line 494, in send_photo
    return _make_request(token, method_url, params=payload, files=files, method='post')
  File "/opt/hostedtoolcache/Python/3.9.18/x64/lib/python3.9/site-packages/telebot/apihelper.py", line 162, in _make_request
    json_result = _check_result(method_name, result)
  File "/opt/hostedtoolcache/Python/3.9.18/x64/lib/python3.9/site-packages/telebot/apihelper.py", line 189, in _check_result
    raise ApiTelegramException(method_name, result, result_json)
telebot.apihelper.ApiTelegramException: A request to the Telegram API was unsuccessful. Error code: 429. Description: Too Many Requests: retry after 15

During handling of the above exception, another exception occurred:

Traceback (most recent call last):
  File "/home/runner/work/FortDaily-PVE_bot/FortDaily-PVE_bot/main.py", line 238, in <module>
    sending()
  File "/home/runner/work/FortDaily-PVE_bot/FortDaily-PVE_bot/main.py", line 211, in sending
    bot.send_message(chat_id=channel_id, text='<u>Сегодня нет V-Bucks</u>')
  File "/opt/hostedtoolcache/Python/3.9.18/x64/lib/python3.9/site-packages/telebot/__init__.py", line 1549, in send_message
    apihelper.send_message(
  File "/opt/hostedtoolcache/Python/3.9.18/x64/lib/python3.9/site-packages/telebot/apihelper.py", line 264, in send_message
    return _make_request(token, method_url, params=payload, method='post')
  File "/opt/hostedtoolcache/Python/3.9.18/x64/lib/python3.9/site-packages/telebot/apihelper.py", line 162, in _make_request
    json_result = _check_result(method_name, result)
  File "/opt/hostedtoolcache/Python/3.9.18/x64/lib/python3.9/site-packages/telebot/apihelper.py", line 189, in _check_result
    raise ApiTelegramException(method_name, result, result_json)
telebot.apihelper.ApiTelegramException: A request to the Telegram API was unsuccessful. Error code: 429. Description: Too Many Requests: retry after 14
00:34:43 - main - WARNING - <module>: 18 - ________________________________HELLO__________________________________
00:35:13 - main - WARNING - sending: 197 - cannot write empty image as JPEG
00:35:35 - main - ERROR - <module>: 240 - A request to the Telegram API was unsuccessful. Error code: 429. Description: Too Many Requests: retry after 24
Traceback (most recent call last):
  File "/home/runner/work/FortDaily-PVE_bot/FortDaily-PVE_bot/main.py", line 193, in sending
    bot.send_photo(chat_id=channel_id, photo=page)
  File "/opt/hostedtoolcache/Python/3.9.18/x64/lib/python3.9/site-packages/telebot/__init__.py", line 1825, in send_photo
    apihelper.send_photo(
  File "/opt/hostedtoolcache/Python/3.9.18/x64/lib/python3.9/site-packages/telebot/apihelper.py", line 469, in send_photo
    files = {'photo': util.pil_image_to_file(photo)}
  File "/opt/hostedtoolcache/Python/3.9.18/x64/lib/python3.9/site-packages/telebot/service_utils.py", line 62, in pil_image_to_file
    image.convert('RGB').save(photoBuffer, extension, quality=quality)
  File "/opt/hostedtoolcache/Python/3.9.18/x64/lib/python3.9/site-packages/PIL/Image.py", line 2432, in save
    save_handler(self, fp, filename)
  File "/opt/hostedtoolcache/Python/3.9.18/x64/lib/python3.9/site-packages/PIL/JpegImagePlugin.py", line 637, in _save
    raise ValueError(msg)
ValueError: cannot write empty image as JPEG

During handling of the above exception, another exception occurred:

Traceback (most recent call last):
  File "/home/runner/work/FortDaily-PVE_bot/FortDaily-PVE_bot/main.py", line 206, in sending
    bot.send_photo(chat_id=channel_id, photo=page)
  File "/opt/hostedtoolcache/Python/3.9.18/x64/lib/python3.9/site-packages/telebot/__init__.py", line 1825, in send_photo
    apihelper.send_photo(
  File "/opt/hostedtoolcache/Python/3.9.18/x64/lib/python3.9/site-packages/telebot/apihelper.py", line 494, in send_photo
    return _make_request(token, method_url, params=payload, files=files, method='post')
  File "/opt/hostedtoolcache/Python/3.9.18/x64/lib/python3.9/site-packages/telebot/apihelper.py", line 162, in _make_request
    json_result = _check_result(method_name, result)
  File "/opt/hostedtoolcache/Python/3.9.18/x64/lib/python3.9/site-packages/telebot/apihelper.py", line 189, in _check_result
    raise ApiTelegramException(method_name, result, result_json)
telebot.apihelper.ApiTelegramException: A request to the Telegram API was unsuccessful. Error code: 429. Description: Too Many Requests: retry after 24

During handling of the above exception, another exception occurred:

Traceback (most recent call last):
  File "/home/runner/work/FortDaily-PVE_bot/FortDaily-PVE_bot/main.py", line 238, in <module>
    sending()
  File "/home/runner/work/FortDaily-PVE_bot/FortDaily-PVE_bot/main.py", line 211, in sending
    bot.send_message(chat_id=channel_id, text='<u>Сегодня нет V-Bucks</u>')
  File "/opt/hostedtoolcache/Python/3.9.18/x64/lib/python3.9/site-packages/telebot/__init__.py", line 1549, in send_message
    apihelper.send_message(
  File "/opt/hostedtoolcache/Python/3.9.18/x64/lib/python3.9/site-packages/telebot/apihelper.py", line 264, in send_message
    return _make_request(token, method_url, params=payload, method='post')
  File "/opt/hostedtoolcache/Python/3.9.18/x64/lib/python3.9/site-packages/telebot/apihelper.py", line 162, in _make_request
    json_result = _check_result(method_name, result)
  File "/opt/hostedtoolcache/Python/3.9.18/x64/lib/python3.9/site-packages/telebot/apihelper.py", line 189, in _check_result
    raise ApiTelegramException(method_name, result, result_json)
telebot.apihelper.ApiTelegramException: A request to the Telegram API was unsuccessful. Error code: 429. Description: Too Many Requests: retry after 24
00:34:04 - main - WARNING - <module>: 18 - ________________________________HELLO__________________________________
00:34:36 - main - WARNING - sending: 197 - cannot write empty image as JPEG
00:35:01 - main - ERROR - <module>: 240 - A request to the Telegram API was unsuccessful. Error code: 429. Description: Too Many Requests: retry after 22
Traceback (most recent call last):
  File "/home/runner/work/FortDaily-PVE_bot/FortDaily-PVE_bot/main.py", line 193, in sending
    bot.send_photo(chat_id=channel_id, photo=page)
  File "/opt/hostedtoolcache/Python/3.9.18/x64/lib/python3.9/site-packages/telebot/__init__.py", line 1825, in send_photo
    apihelper.send_photo(
  File "/opt/hostedtoolcache/Python/3.9.18/x64/lib/python3.9/site-packages/telebot/apihelper.py", line 469, in send_photo
    files = {'photo': util.pil_image_to_file(photo)}
  File "/opt/hostedtoolcache/Python/3.9.18/x64/lib/python3.9/site-packages/telebot/service_utils.py", line 62, in pil_image_to_file
    image.convert('RGB').save(photoBuffer, extension, quality=quality)
  File "/opt/hostedtoolcache/Python/3.9.18/x64/lib/python3.9/site-packages/PIL/Image.py", line 2432, in save
    save_handler(self, fp, filename)
  File "/opt/hostedtoolcache/Python/3.9.18/x64/lib/python3.9/site-packages/PIL/JpegImagePlugin.py", line 637, in _save
    raise ValueError(msg)
ValueError: cannot write empty image as JPEG

During handling of the above exception, another exception occurred:

Traceback (most recent call last):
  File "/home/runner/work/FortDaily-PVE_bot/FortDaily-PVE_bot/main.py", line 206, in sending
    bot.send_photo(chat_id=channel_id, photo=page)
  File "/opt/hostedtoolcache/Python/3.9.18/x64/lib/python3.9/site-packages/telebot/__init__.py", line 1825, in send_photo
    apihelper.send_photo(
  File "/opt/hostedtoolcache/Python/3.9.18/x64/lib/python3.9/site-packages/telebot/apihelper.py", line 494, in send_photo
    return _make_request(token, method_url, params=payload, files=files, method='post')
  File "/opt/hostedtoolcache/Python/3.9.18/x64/lib/python3.9/site-packages/telebot/apihelper.py", line 162, in _make_request
    json_result = _check_result(method_name, result)
  File "/opt/hostedtoolcache/Python/3.9.18/x64/lib/python3.9/site-packages/telebot/apihelper.py", line 189, in _check_result
    raise ApiTelegramException(method_name, result, result_json)
telebot.apihelper.ApiTelegramException: A request to the Telegram API was unsuccessful. Error code: 429. Description: Too Many Requests: retry after 23

During handling of the above exception, another exception occurred:

Traceback (most recent call last):
  File "/home/runner/work/FortDaily-PVE_bot/FortDaily-PVE_bot/main.py", line 238, in <module>
    sending()
  File "/home/runner/work/FortDaily-PVE_bot/FortDaily-PVE_bot/main.py", line 213, in sending
    bot.send_message(chat_id=channel_id, text=alerts)
  File "/opt/hostedtoolcache/Python/3.9.18/x64/lib/python3.9/site-packages/telebot/__init__.py", line 1549, in send_message
    apihelper.send_message(
  File "/opt/hostedtoolcache/Python/3.9.18/x64/lib/python3.9/site-packages/telebot/apihelper.py", line 264, in send_message
    return _make_request(token, method_url, params=payload, method='post')
  File "/opt/hostedtoolcache/Python/3.9.18/x64/lib/python3.9/site-packages/telebot/apihelper.py", line 162, in _make_request
    json_result = _check_result(method_name, result)
  File "/opt/hostedtoolcache/Python/3.9.18/x64/lib/python3.9/site-packages/telebot/apihelper.py", line 189, in _check_result
    raise ApiTelegramException(method_name, result, result_json)
telebot.apihelper.ApiTelegramException: A request to the Telegram API was unsuccessful. Error code: 429. Description: Too Many Requests: retry after 22
00:34:34 - main - WARNING - <module>: 18 - ________________________________HELLO__________________________________
00:34:43 - main - WARNING - sending: 197 - cannot write empty image as JPEG
00:33:23 - main - WARNING - <module>: 18 - ________________________________HELLO__________________________________
00:33:36 - main - WARNING - sending: 197 - cannot write empty image as JPEG
00:37:08 - main - WARNING - <module>: 18 - ________________________________HELLO__________________________________
00:35:13 - main - WARNING - <module>: 18 - ________________________________HELLO__________________________________
00:35:13 - main - WARNING - sending: 197 - cannot write empty image as JPEG
00:35:15 - main - ERROR - <module>: 240 - cannot write empty image as JPEG
Traceback (most recent call last):
  File "/home/runner/work/FortDaily-PVE_bot/FortDaily-PVE_bot/main.py", line 193, in sending
    bot.send_photo(chat_id=channel_id, photo=page)
  File "/opt/hostedtoolcache/Python/3.9.18/x64/lib/python3.9/site-packages/telebot/__init__.py", line 1825, in send_photo
    apihelper.send_photo(
  File "/opt/hostedtoolcache/Python/3.9.18/x64/lib/python3.9/site-packages/telebot/apihelper.py", line 469, in send_photo
    files = {'photo': util.pil_image_to_file(photo)}
  File "/opt/hostedtoolcache/Python/3.9.18/x64/lib/python3.9/site-packages/telebot/service_utils.py", line 62, in pil_image_to_file
    image.convert('RGB').save(photoBuffer, extension, quality=quality)
  File "/opt/hostedtoolcache/Python/3.9.18/x64/lib/python3.9/site-packages/PIL/Image.py", line 2432, in save
    save_handler(self, fp, filename)
  File "/opt/hostedtoolcache/Python/3.9.18/x64/lib/python3.9/site-packages/PIL/JpegImagePlugin.py", line 637, in _save
    raise ValueError(msg)
ValueError: cannot write empty image as JPEG

During handling of the above exception, another exception occurred:

Traceback (most recent call last):
  File "/home/runner/work/FortDaily-PVE_bot/FortDaily-PVE_bot/main.py", line 238, in <module>
    sending()
  File "/home/runner/work/FortDaily-PVE_bot/FortDaily-PVE_bot/main.py", line 206, in sending
    bot.send_photo(chat_id=channel_id, photo=page)
  File "/opt/hostedtoolcache/Python/3.9.18/x64/lib/python3.9/site-packages/telebot/__init__.py", line 1825, in send_photo
    apihelper.send_photo(
  File "/opt/hostedtoolcache/Python/3.9.18/x64/lib/python3.9/site-packages/telebot/apihelper.py", line 469, in send_photo
    files = {'photo': util.pil_image_to_file(photo)}
  File "/opt/hostedtoolcache/Python/3.9.18/x64/lib/python3.9/site-packages/telebot/service_utils.py", line 62, in pil_image_to_file
    image.convert('RGB').save(photoBuffer, extension, quality=quality)
  File "/opt/hostedtoolcache/Python/3.9.18/x64/lib/python3.9/site-packages/PIL/Image.py", line 2432, in save
    save_handler(self, fp, filename)
  File "/opt/hostedtoolcache/Python/3.9.18/x64/lib/python3.9/site-packages/PIL/JpegImagePlugin.py", line 637, in _save
    raise ValueError(msg)
ValueError: cannot write empty image as JPEG
00:34:51 - main - WARNING - <module>: 18 - ________________________________HELLO__________________________________
00:34:15 - main - WARNING - <module>: 18 - ________________________________HELLO__________________________________
00:33:48 - main - WARNING - <module>: 18 - ________________________________HELLO__________________________________
00:34:37 - main - WARNING - <module>: 18 - ________________________________HELLO__________________________________
00:33:49 - main - WARNING - <module>: 18 - ________________________________HELLO__________________________________
00:37:13 - main - WARNING - <module>: 18 - ________________________________HELLO__________________________________
00:35:14 - main - WARNING - <module>: 18 - ________________________________HELLO__________________________________
00:34:26 - main - WARNING - <module>: 18 - ________________________________HELLO__________________________________
00:27:42 - main - WARNING - <module>: 18 - ________________________________HELLO__________________________________
00:33:44 - main - WARNING - <module>: 18 - ________________________________HELLO__________________________________
00:33:35 - main - WARNING - <module>: 18 - ________________________________HELLO__________________________________
00:32:08 - main - WARNING - <module>: 18 - ________________________________HELLO__________________________________
00:36:23 - main - WARNING - <module>: 18 - ________________________________HELLO__________________________________
00:34:32 - main - WARNING - <module>: 18 - ________________________________HELLO__________________________________
00:35:02 - main - WARNING - sending: 197 - cannot write empty image as JPEG
00:35:29 - main - ERROR - <module>: 240 - A request to the Telegram API was unsuccessful. Error code: 429. Description: Too Many Requests: retry after 23
Traceback (most recent call last):
  File "/home/runner/work/FortDaily-PVE_bot/FortDaily-PVE_bot/main.py", line 193, in sending
    bot.send_photo(chat_id=channel_id, photo=page)
  File "/opt/hostedtoolcache/Python/3.9.18/x64/lib/python3.9/site-packages/telebot/__init__.py", line 1825, in send_photo
    apihelper.send_photo(
  File "/opt/hostedtoolcache/Python/3.9.18/x64/lib/python3.9/site-packages/telebot/apihelper.py", line 469, in send_photo
    files = {'photo': util.pil_image_to_file(photo)}
  File "/opt/hostedtoolcache/Python/3.9.18/x64/lib/python3.9/site-packages/telebot/service_utils.py", line 62, in pil_image_to_file
    image.convert('RGB').save(photoBuffer, extension, quality=quality)
  File "/opt/hostedtoolcache/Python/3.9.18/x64/lib/python3.9/site-packages/PIL/Image.py", line 2432, in save
    save_handler(self, fp, filename)
  File "/opt/hostedtoolcache/Python/3.9.18/x64/lib/python3.9/site-packages/PIL/JpegImagePlugin.py", line 637, in _save
    raise ValueError(msg)
ValueError: cannot write empty image as JPEG

During handling of the above exception, another exception occurred:

Traceback (most recent call last):
  File "/home/runner/work/FortDaily-PVE_bot/FortDaily-PVE_bot/main.py", line 206, in sending
    bot.send_photo(chat_id=channel_id, photo=page)
  File "/opt/hostedtoolcache/Python/3.9.18/x64/lib/python3.9/site-packages/telebot/__init__.py", line 1825, in send_photo
    apihelper.send_photo(
  File "/opt/hostedtoolcache/Python/3.9.18/x64/lib/python3.9/site-packages/telebot/apihelper.py", line 469, in send_photo
    files = {'photo': util.pil_image_to_file(photo)}
  File "/opt/hostedtoolcache/Python/3.9.18/x64/lib/python3.9/site-packages/telebot/service_utils.py", line 62, in pil_image_to_file
    image.convert('RGB').save(photoBuffer, extension, quality=quality)
  File "/opt/hostedtoolcache/Python/3.9.18/x64/lib/python3.9/site-packages/PIL/Image.py", line 2432, in save
    save_handler(self, fp, filename)
  File "/opt/hostedtoolcache/Python/3.9.18/x64/lib/python3.9/site-packages/PIL/JpegImagePlugin.py", line 637, in _save
    raise ValueError(msg)
ValueError: cannot write empty image as JPEG

During handling of the above exception, another exception occurred:

Traceback (most recent call last):
  File "/home/runner/work/FortDaily-PVE_bot/FortDaily-PVE_bot/main.py", line 238, in <module>
    sending()
  File "/home/runner/work/FortDaily-PVE_bot/FortDaily-PVE_bot/main.py", line 211, in sending
    bot.send_message(chat_id=channel_id, text='<u>Сегодня нет V-Bucks</u>')
  File "/opt/hostedtoolcache/Python/3.9.18/x64/lib/python3.9/site-packages/telebot/__init__.py", line 1549, in send_message
    apihelper.send_message(
  File "/opt/hostedtoolcache/Python/3.9.18/x64/lib/python3.9/site-packages/telebot/apihelper.py", line 264, in send_message
    return _make_request(token, method_url, params=payload, method='post')
  File "/opt/hostedtoolcache/Python/3.9.18/x64/lib/python3.9/site-packages/telebot/apihelper.py", line 162, in _make_request
    json_result = _check_result(method_name, result)
  File "/opt/hostedtoolcache/Python/3.9.18/x64/lib/python3.9/site-packages/telebot/apihelper.py", line 189, in _check_result
    raise ApiTelegramException(method_name, result, result_json)
telebot.apihelper.ApiTelegramException: A request to the Telegram API was unsuccessful. Error code: 429. Description: Too Many Requests: retry after 23
00:32:50 - main - WARNING - <module>: 18 - ________________________________HELLO__________________________________
00:33:16 - main - WARNING - sending: 197 - cannot write empty image as JPEG
00:33:43 - main - ERROR - <module>: 240 - cannot write empty image as JPEG
Traceback (most recent call last):
  File "/home/runner/work/FortDaily-PVE_bot/FortDaily-PVE_bot/main.py", line 193, in sending
    bot.send_photo(chat_id=channel_id, photo=page)
  File "/opt/hostedtoolcache/Python/3.9.18/x64/lib/python3.9/site-packages/telebot/__init__.py", line 1825, in send_photo
    apihelper.send_photo(
  File "/opt/hostedtoolcache/Python/3.9.18/x64/lib/python3.9/site-packages/telebot/apihelper.py", line 469, in send_photo
    files = {'photo': util.pil_image_to_file(photo)}
  File "/opt/hostedtoolcache/Python/3.9.18/x64/lib/python3.9/site-packages/telebot/service_utils.py", line 62, in pil_image_to_file
    image.convert('RGB').save(photoBuffer, extension, quality=quality)
  File "/opt/hostedtoolcache/Python/3.9.18/x64/lib/python3.9/site-packages/PIL/Image.py", line 2432, in save
    save_handler(self, fp, filename)
  File "/opt/hostedtoolcache/Python/3.9.18/x64/lib/python3.9/site-packages/PIL/JpegImagePlugin.py", line 637, in _save
    raise ValueError(msg)
ValueError: cannot write empty image as JPEG

During handling of the above exception, another exception occurred:

Traceback (most recent call last):
  File "/home/runner/work/FortDaily-PVE_bot/FortDaily-PVE_bot/main.py", line 238, in <module>
    sending()
  File "/home/runner/work/FortDaily-PVE_bot/FortDaily-PVE_bot/main.py", line 206, in sending
    bot.send_photo(chat_id=channel_id, photo=page)
  File "/opt/hostedtoolcache/Python/3.9.18/x64/lib/python3.9/site-packages/telebot/__init__.py", line 1825, in send_photo
    apihelper.send_photo(
  File "/opt/hostedtoolcache/Python/3.9.18/x64/lib/python3.9/site-packages/telebot/apihelper.py", line 469, in send_photo
    files = {'photo': util.pil_image_to_file(photo)}
  File "/opt/hostedtoolcache/Python/3.9.18/x64/lib/python3.9/site-packages/telebot/service_utils.py", line 62, in pil_image_to_file
    image.convert('RGB').save(photoBuffer, extension, quality=quality)
  File "/opt/hostedtoolcache/Python/3.9.18/x64/lib/python3.9/site-packages/PIL/Image.py", line 2432, in save
    save_handler(self, fp, filename)
  File "/opt/hostedtoolcache/Python/3.9.18/x64/lib/python3.9/site-packages/PIL/JpegImagePlugin.py", line 637, in _save
    raise ValueError(msg)
ValueError: cannot write empty image as JPEG
00:32:47 - main - WARNING - <module>: 18 - ________________________________HELLO__________________________________
00:33:08 - main - WARNING - sending: 197 - cannot write empty image as JPEG
00:33:32 - main - ERROR - <module>: 240 - cannot write empty image as JPEG
Traceback (most recent call last):
  File "/home/runner/work/FortDaily-PVE_bot/FortDaily-PVE_bot/main.py", line 193, in sending
    bot.send_photo(chat_id=channel_id, photo=page)
  File "/opt/hostedtoolcache/Python/3.9.18/x64/lib/python3.9/site-packages/telebot/__init__.py", line 1825, in send_photo
    apihelper.send_photo(
  File "/opt/hostedtoolcache/Python/3.9.18/x64/lib/python3.9/site-packages/telebot/apihelper.py", line 469, in send_photo
    files = {'photo': util.pil_image_to_file(photo)}
  File "/opt/hostedtoolcache/Python/3.9.18/x64/lib/python3.9/site-packages/telebot/service_utils.py", line 62, in pil_image_to_file
    image.convert('RGB').save(photoBuffer, extension, quality=quality)
  File "/opt/hostedtoolcache/Python/3.9.18/x64/lib/python3.9/site-packages/PIL/Image.py", line 2432, in save
    save_handler(self, fp, filename)
  File "/opt/hostedtoolcache/Python/3.9.18/x64/lib/python3.9/site-packages/PIL/JpegImagePlugin.py", line 637, in _save
    raise ValueError(msg)
ValueError: cannot write empty image as JPEG

During handling of the above exception, another exception occurred:

Traceback (most recent call last):
  File "/home/runner/work/FortDaily-PVE_bot/FortDaily-PVE_bot/main.py", line 238, in <module>
    sending()
  File "/home/runner/work/FortDaily-PVE_bot/FortDaily-PVE_bot/main.py", line 206, in sending
    bot.send_photo(chat_id=channel_id, photo=page)
  File "/opt/hostedtoolcache/Python/3.9.18/x64/lib/python3.9/site-packages/telebot/__init__.py", line 1825, in send_photo
    apihelper.send_photo(
  File "/opt/hostedtoolcache/Python/3.9.18/x64/lib/python3.9/site-packages/telebot/apihelper.py", line 469, in send_photo
    files = {'photo': util.pil_image_to_file(photo)}
  File "/opt/hostedtoolcache/Python/3.9.18/x64/lib/python3.9/site-packages/telebot/service_utils.py", line 62, in pil_image_to_file
    image.convert('RGB').save(photoBuffer, extension, quality=quality)
  File "/opt/hostedtoolcache/Python/3.9.18/x64/lib/python3.9/site-packages/PIL/Image.py", line 2432, in save
    save_handler(self, fp, filename)
  File "/opt/hostedtoolcache/Python/3.9.18/x64/lib/python3.9/site-packages/PIL/JpegImagePlugin.py", line 637, in _save
    raise ValueError(msg)
ValueError: cannot write empty image as JPEG
00:32:41 - main - WARNING - <module>: 18 - ________________________________HELLO__________________________________
00:33:07 - main - WARNING - sending: 197 - cannot write empty image as JPEG
00:33:32 - main - ERROR - <module>: 240 - A request to the Telegram API was unsuccessful. Error code: 429. Description: Too Many Requests: retry after 25
Traceback (most recent call last):
  File "/home/runner/work/FortDaily-PVE_bot/FortDaily-PVE_bot/main.py", line 193, in sending
    bot.send_photo(chat_id=channel_id, photo=page)
  File "/opt/hostedtoolcache/Python/3.9.18/x64/lib/python3.9/site-packages/telebot/__init__.py", line 1825, in send_photo
    apihelper.send_photo(
  File "/opt/hostedtoolcache/Python/3.9.18/x64/lib/python3.9/site-packages/telebot/apihelper.py", line 469, in send_photo
    files = {'photo': util.pil_image_to_file(photo)}
  File "/opt/hostedtoolcache/Python/3.9.18/x64/lib/python3.9/site-packages/telebot/service_utils.py", line 62, in pil_image_to_file
    image.convert('RGB').save(photoBuffer, extension, quality=quality)
  File "/opt/hostedtoolcache/Python/3.9.18/x64/lib/python3.9/site-packages/PIL/Image.py", line 2432, in save
    save_handler(self, fp, filename)
  File "/opt/hostedtoolcache/Python/3.9.18/x64/lib/python3.9/site-packages/PIL/JpegImagePlugin.py", line 637, in _save
    raise ValueError(msg)
ValueError: cannot write empty image as JPEG

During handling of the above exception, another exception occurred:

Traceback (most recent call last):
  File "/home/runner/work/FortDaily-PVE_bot/FortDaily-PVE_bot/main.py", line 206, in sending
    bot.send_photo(chat_id=channel_id, photo=page)
  File "/opt/hostedtoolcache/Python/3.9.18/x64/lib/python3.9/site-packages/telebot/__init__.py", line 1825, in send_photo
    apihelper.send_photo(
  File "/opt/hostedtoolcache/Python/3.9.18/x64/lib/python3.9/site-packages/telebot/apihelper.py", line 469, in send_photo
    files = {'photo': util.pil_image_to_file(photo)}
  File "/opt/hostedtoolcache/Python/3.9.18/x64/lib/python3.9/site-packages/telebot/service_utils.py", line 62, in pil_image_to_file
    image.convert('RGB').save(photoBuffer, extension, quality=quality)
  File "/opt/hostedtoolcache/Python/3.9.18/x64/lib/python3.9/site-packages/PIL/Image.py", line 2432, in save
    save_handler(self, fp, filename)
  File "/opt/hostedtoolcache/Python/3.9.18/x64/lib/python3.9/site-packages/PIL/JpegImagePlugin.py", line 637, in _save
    raise ValueError(msg)
ValueError: cannot write empty image as JPEG

During handling of the above exception, another exception occurred:

Traceback (most recent call last):
  File "/home/runner/work/FortDaily-PVE_bot/FortDaily-PVE_bot/main.py", line 238, in <module>
    sending()
  File "/home/runner/work/FortDaily-PVE_bot/FortDaily-PVE_bot/main.py", line 211, in sending
    bot.send_message(chat_id=channel_id, text='<u>Сегодня нет V-Bucks</u>')
  File "/opt/hostedtoolcache/Python/3.9.18/x64/lib/python3.9/site-packages/telebot/__init__.py", line 1549, in send_message
    apihelper.send_message(
  File "/opt/hostedtoolcache/Python/3.9.18/x64/lib/python3.9/site-packages/telebot/apihelper.py", line 264, in send_message
    return _make_request(token, method_url, params=payload, method='post')
  File "/opt/hostedtoolcache/Python/3.9.18/x64/lib/python3.9/site-packages/telebot/apihelper.py", line 162, in _make_request
    json_result = _check_result(method_name, result)
  File "/opt/hostedtoolcache/Python/3.9.18/x64/lib/python3.9/site-packages/telebot/apihelper.py", line 189, in _check_result
    raise ApiTelegramException(method_name, result, result_json)
telebot.apihelper.ApiTelegramException: A request to the Telegram API was unsuccessful. Error code: 429. Description: Too Many Requests: retry after 25
00:27:21 - main - WARNING - <module>: 18 - ________________________________HELLO__________________________________
00:27:48 - main - WARNING - sending: 197 - cannot write empty image as JPEG
00:28:14 - main - ERROR - <module>: 240 - cannot write empty image as JPEG
Traceback (most recent call last):
  File "/home/runner/work/FortDaily-PVE_bot/FortDaily-PVE_bot/main.py", line 193, in sending
    bot.send_photo(chat_id=channel_id, photo=page)
  File "/opt/hostedtoolcache/Python/3.9.18/x64/lib/python3.9/site-packages/telebot/__init__.py", line 1825, in send_photo
    apihelper.send_photo(
  File "/opt/hostedtoolcache/Python/3.9.18/x64/lib/python3.9/site-packages/telebot/apihelper.py", line 469, in send_photo
    files = {'photo': util.pil_image_to_file(photo)}
  File "/opt/hostedtoolcache/Python/3.9.18/x64/lib/python3.9/site-packages/telebot/service_utils.py", line 62, in pil_image_to_file
    image.convert('RGB').save(photoBuffer, extension, quality=quality)
  File "/opt/hostedtoolcache/Python/3.9.18/x64/lib/python3.9/site-packages/PIL/Image.py", line 2432, in save
    save_handler(self, fp, filename)
  File "/opt/hostedtoolcache/Python/3.9.18/x64/lib/python3.9/site-packages/PIL/JpegImagePlugin.py", line 637, in _save
    raise ValueError(msg)
ValueError: cannot write empty image as JPEG

During handling of the above exception, another exception occurred:

Traceback (most recent call last):
  File "/home/runner/work/FortDaily-PVE_bot/FortDaily-PVE_bot/main.py", line 238, in <module>
    sending()
  File "/home/runner/work/FortDaily-PVE_bot/FortDaily-PVE_bot/main.py", line 206, in sending
    bot.send_photo(chat_id=channel_id, photo=page)
  File "/opt/hostedtoolcache/Python/3.9.18/x64/lib/python3.9/site-packages/telebot/__init__.py", line 1825, in send_photo
    apihelper.send_photo(
  File "/opt/hostedtoolcache/Python/3.9.18/x64/lib/python3.9/site-packages/telebot/apihelper.py", line 469, in send_photo
    files = {'photo': util.pil_image_to_file(photo)}
  File "/opt/hostedtoolcache/Python/3.9.18/x64/lib/python3.9/site-packages/telebot/service_utils.py", line 62, in pil_image_to_file
    image.convert('RGB').save(photoBuffer, extension, quality=quality)
  File "/opt/hostedtoolcache/Python/3.9.18/x64/lib/python3.9/site-packages/PIL/Image.py", line 2432, in save
    save_handler(self, fp, filename)
  File "/opt/hostedtoolcache/Python/3.9.18/x64/lib/python3.9/site-packages/PIL/JpegImagePlugin.py", line 637, in _save
    raise ValueError(msg)
ValueError: cannot write empty image as JPEG
00:32:41 - main - WARNING - <module>: 18 - ________________________________HELLO__________________________________
00:33:09 - main - WARNING - sending: 197 - cannot write empty image as JPEG
00:33:36 - main - ERROR - <module>: 240 - cannot write empty image as JPEG
Traceback (most recent call last):
  File "/home/runner/work/FortDaily-PVE_bot/FortDaily-PVE_bot/main.py", line 193, in sending
    bot.send_photo(chat_id=channel_id, photo=page)
  File "/opt/hostedtoolcache/Python/3.9.18/x64/lib/python3.9/site-packages/telebot/__init__.py", line 1825, in send_photo
    apihelper.send_photo(
  File "/opt/hostedtoolcache/Python/3.9.18/x64/lib/python3.9/site-packages/telebot/apihelper.py", line 469, in send_photo
    files = {'photo': util.pil_image_to_file(photo)}
  File "/opt/hostedtoolcache/Python/3.9.18/x64/lib/python3.9/site-packages/telebot/service_utils.py", line 62, in pil_image_to_file
    image.convert('RGB').save(photoBuffer, extension, quality=quality)
  File "/opt/hostedtoolcache/Python/3.9.18/x64/lib/python3.9/site-packages/PIL/Image.py", line 2432, in save
    save_handler(self, fp, filename)
  File "/opt/hostedtoolcache/Python/3.9.18/x64/lib/python3.9/site-packages/PIL/JpegImagePlugin.py", line 637, in _save
    raise ValueError(msg)
ValueError: cannot write empty image as JPEG

During handling of the above exception, another exception occurred:

Traceback (most recent call last):
  File "/home/runner/work/FortDaily-PVE_bot/FortDaily-PVE_bot/main.py", line 238, in <module>
    sending()
  File "/home/runner/work/FortDaily-PVE_bot/FortDaily-PVE_bot/main.py", line 206, in sending
    bot.send_photo(chat_id=channel_id, photo=page)
  File "/opt/hostedtoolcache/Python/3.9.18/x64/lib/python3.9/site-packages/telebot/__init__.py", line 1825, in send_photo
    apihelper.send_photo(
  File "/opt/hostedtoolcache/Python/3.9.18/x64/lib/python3.9/site-packages/telebot/apihelper.py", line 469, in send_photo
    files = {'photo': util.pil_image_to_file(photo)}
  File "/opt/hostedtoolcache/Python/3.9.18/x64/lib/python3.9/site-packages/telebot/service_utils.py", line 62, in pil_image_to_file
    image.convert('RGB').save(photoBuffer, extension, quality=quality)
  File "/opt/hostedtoolcache/Python/3.9.18/x64/lib/python3.9/site-packages/PIL/Image.py", line 2432, in save
    save_handler(self, fp, filename)
  File "/opt/hostedtoolcache/Python/3.9.18/x64/lib/python3.9/site-packages/PIL/JpegImagePlugin.py", line 637, in _save
    raise ValueError(msg)
ValueError: cannot write empty image as JPEG
00:36:46 - main - WARNING - <module>: 18 - ________________________________HELLO__________________________________
00:37:17 - main - WARNING - sending: 197 - cannot write empty image as JPEG
00:37:44 - main - ERROR - <module>: 240 - A request to the Telegram API was unsuccessful. Error code: 429. Description: Too Many Requests: retry after 20
Traceback (most recent call last):
  File "/home/runner/work/FortDaily-PVE_bot/FortDaily-PVE_bot/main.py", line 193, in sending
    bot.send_photo(chat_id=channel_id, photo=page)
  File "/opt/hostedtoolcache/Python/3.9.18/x64/lib/python3.9/site-packages/telebot/__init__.py", line 1825, in send_photo
    apihelper.send_photo(
  File "/opt/hostedtoolcache/Python/3.9.18/x64/lib/python3.9/site-packages/telebot/apihelper.py", line 469, in send_photo
    files = {'photo': util.pil_image_to_file(photo)}
  File "/opt/hostedtoolcache/Python/3.9.18/x64/lib/python3.9/site-packages/telebot/service_utils.py", line 62, in pil_image_to_file
    image.convert('RGB').save(photoBuffer, extension, quality=quality)
  File "/opt/hostedtoolcache/Python/3.9.18/x64/lib/python3.9/site-packages/PIL/Image.py", line 2432, in save
    save_handler(self, fp, filename)
  File "/opt/hostedtoolcache/Python/3.9.18/x64/lib/python3.9/site-packages/PIL/JpegImagePlugin.py", line 637, in _save
    raise ValueError(msg)
ValueError: cannot write empty image as JPEG

During handling of the above exception, another exception occurred:

Traceback (most recent call last):
  File "/home/runner/work/FortDaily-PVE_bot/FortDaily-PVE_bot/main.py", line 206, in sending
    bot.send_photo(chat_id=channel_id, photo=page)
  File "/opt/hostedtoolcache/Python/3.9.18/x64/lib/python3.9/site-packages/telebot/__init__.py", line 1825, in send_photo
    apihelper.send_photo(
  File "/opt/hostedtoolcache/Python/3.9.18/x64/lib/python3.9/site-packages/telebot/apihelper.py", line 494, in send_photo
    return _make_request(token, method_url, params=payload, files=files, method='post')
  File "/opt/hostedtoolcache/Python/3.9.18/x64/lib/python3.9/site-packages/telebot/apihelper.py", line 162, in _make_request
    json_result = _check_result(method_name, result)
  File "/opt/hostedtoolcache/Python/3.9.18/x64/lib/python3.9/site-packages/telebot/apihelper.py", line 189, in _check_result
    raise ApiTelegramException(method_name, result, result_json)
telebot.apihelper.ApiTelegramException: A request to the Telegram API was unsuccessful. Error code: 429. Description: Too Many Requests: retry after 20

During handling of the above exception, another exception occurred:

Traceback (most recent call last):
  File "/home/runner/work/FortDaily-PVE_bot/FortDaily-PVE_bot/main.py", line 238, in <module>
    sending()
  File "/home/runner/work/FortDaily-PVE_bot/FortDaily-PVE_bot/main.py", line 211, in sending
    bot.send_message(chat_id=channel_id, text='<u>Сегодня нет V-Bucks</u>')
  File "/opt/hostedtoolcache/Python/3.9.18/x64/lib/python3.9/site-packages/telebot/__init__.py", line 1549, in send_message
    apihelper.send_message(
  File "/opt/hostedtoolcache/Python/3.9.18/x64/lib/python3.9/site-packages/telebot/apihelper.py", line 264, in send_message
    return _make_request(token, method_url, params=payload, method='post')
  File "/opt/hostedtoolcache/Python/3.9.18/x64/lib/python3.9/site-packages/telebot/apihelper.py", line 162, in _make_request
    json_result = _check_result(method_name, result)
  File "/opt/hostedtoolcache/Python/3.9.18/x64/lib/python3.9/site-packages/telebot/apihelper.py", line 189, in _check_result
    raise ApiTelegramException(method_name, result, result_json)
telebot.apihelper.ApiTelegramException: A request to the Telegram API was unsuccessful. Error code: 429. Description: Too Many Requests: retry after 20
00:38:01 - main - WARNING - <module>: 18 - ________________________________HELLO__________________________________
00:38:28 - main - WARNING - sending: 197 - cannot write empty image as JPEG
00:38:50 - main - ERROR - <module>: 240 - cannot write empty image as JPEG
Traceback (most recent call last):
  File "/home/runner/work/FortDaily-PVE_bot/FortDaily-PVE_bot/main.py", line 193, in sending
    bot.send_photo(chat_id=channel_id, photo=page)
  File "/opt/hostedtoolcache/Python/3.9.18/x64/lib/python3.9/site-packages/telebot/__init__.py", line 1825, in send_photo
    apihelper.send_photo(
  File "/opt/hostedtoolcache/Python/3.9.18/x64/lib/python3.9/site-packages/telebot/apihelper.py", line 469, in send_photo
    files = {'photo': util.pil_image_to_file(photo)}
  File "/opt/hostedtoolcache/Python/3.9.18/x64/lib/python3.9/site-packages/telebot/service_utils.py", line 62, in pil_image_to_file
    image.convert('RGB').save(photoBuffer, extension, quality=quality)
  File "/opt/hostedtoolcache/Python/3.9.18/x64/lib/python3.9/site-packages/PIL/Image.py", line 2432, in save
    save_handler(self, fp, filename)
  File "/opt/hostedtoolcache/Python/3.9.18/x64/lib/python3.9/site-packages/PIL/JpegImagePlugin.py", line 637, in _save
    raise ValueError(msg)
ValueError: cannot write empty image as JPEG

During handling of the above exception, another exception occurred:

Traceback (most recent call last):
  File "/home/runner/work/FortDaily-PVE_bot/FortDaily-PVE_bot/main.py", line 238, in <module>
    sending()
  File "/home/runner/work/FortDaily-PVE_bot/FortDaily-PVE_bot/main.py", line 206, in sending
    bot.send_photo(chat_id=channel_id, photo=page)
  File "/opt/hostedtoolcache/Python/3.9.18/x64/lib/python3.9/site-packages/telebot/__init__.py", line 1825, in send_photo
    apihelper.send_photo(
  File "/opt/hostedtoolcache/Python/3.9.18/x64/lib/python3.9/site-packages/telebot/apihelper.py", line 469, in send_photo
    files = {'photo': util.pil_image_to_file(photo)}
  File "/opt/hostedtoolcache/Python/3.9.18/x64/lib/python3.9/site-packages/telebot/service_utils.py", line 62, in pil_image_to_file
    image.convert('RGB').save(photoBuffer, extension, quality=quality)
  File "/opt/hostedtoolcache/Python/3.9.18/x64/lib/python3.9/site-packages/PIL/Image.py", line 2432, in save
    save_handler(self, fp, filename)
  File "/opt/hostedtoolcache/Python/3.9.18/x64/lib/python3.9/site-packages/PIL/JpegImagePlugin.py", line 637, in _save
    raise ValueError(msg)
ValueError: cannot write empty image as JPEG
00:33:26 - main - WARNING - <module>: 18 - ________________________________HELLO__________________________________
00:33:41 - main - WARNING - <module>: 18 - ________________________________HELLO__________________________________
00:34:25 - main - WARNING - <module>: 18 - ________________________________HELLO__________________________________
00:34:23 - main - WARNING - <module>: 18 - ________________________________HELLO__________________________________
00:33:50 - main - WARNING - <module>: 18 - ________________________________HELLO__________________________________
00:37:42 - main - WARNING - <module>: 18 - ________________________________HELLO__________________________________
00:35:34 - main - WARNING - <module>: 18 - ________________________________HELLO__________________________________
00:35:03 - main - WARNING - <module>: 18 - ________________________________HELLO__________________________________
00:34:57 - main - WARNING - <module>: 18 - ________________________________HELLO__________________________________
00:34:43 - main - WARNING - <module>: 18 - ________________________________HELLO__________________________________
00:34:46 - main - WARNING - <module>: 18 - ________________________________HELLO__________________________________
00:34:20 - main - WARNING - <module>: 18 - ________________________________HELLO__________________________________
00:38:04 - main - WARNING - <module>: 18 - ________________________________HELLO__________________________________
00:36:27 - main - WARNING - <module>: 18 - ________________________________HELLO__________________________________
00:34:40 - main - WARNING - <module>: 18 - ________________________________HELLO__________________________________
00:35:14 - main - WARNING - <module>: 18 - ________________________________HELLO__________________________________
00:34:34 - main - WARNING - <module>: 18 - ________________________________HELLO__________________________________
00:35:09 - main - WARNING - <module>: 18 - ________________________________HELLO__________________________________
00:34:20 - main - WARNING - <module>: 18 - ________________________________HELLO__________________________________
00:37:54 - main - WARNING - <module>: 18 - ________________________________HELLO__________________________________
00:36:46 - main - WARNING - <module>: 18 - ________________________________HELLO__________________________________
00:35:20 - main - WARNING - <module>: 18 - ________________________________HELLO__________________________________
00:35:27 - main - WARNING - <module>: 18 - ________________________________HELLO__________________________________
00:35:34 - main - WARNING - <module>: 18 - ________________________________HELLO__________________________________
00:32:48 - main - WARNING - <module>: 18 - ________________________________HELLO__________________________________
00:32:25 - main - WARNING - <module>: 18 - ________________________________HELLO__________________________________
00:34:56 - main - WARNING - <module>: 18 - ________________________________HELLO__________________________________
00:32:35 - main - WARNING - <module>: 18 - ________________________________HELLO__________________________________
00:32:29 - main - WARNING - <module>: 18 - ________________________________HELLO__________________________________
00:32:51 - main - WARNING - <module>: 18 - ________________________________HELLO__________________________________
00:34:08 - main - WARNING - <module>: 18 - ________________________________HELLO__________________________________
00:32:38 - main - WARNING - <module>: 18 - ________________________________HELLO__________________________________
00:32:25 - main - WARNING - <module>: 18 - ________________________________HELLO__________________________________
00:35:35 - main - WARNING - <module>: 18 - ________________________________HELLO__________________________________
00:33:51 - main - WARNING - <module>: 18 - ________________________________HELLO__________________________________
00:32:16 - main - WARNING - <module>: 18 - ________________________________HELLO__________________________________
00:31:02 - main - WARNING - <module>: 18 - ________________________________HELLO__________________________________
00:32:12 - main - WARNING - <module>: 18 - ________________________________HELLO__________________________________
00:31:46 - main - WARNING - <module>: 18 - ________________________________HELLO__________________________________
00:31:40 - main - WARNING - <module>: 18 - ________________________________HELLO__________________________________
00:35:27 - main - WARNING - <module>: 18 - ________________________________HELLO__________________________________
00:33:14 - main - WARNING - <module>: 18 - ________________________________HELLO__________________________________
00:34:49 - main - WARNING - <module>: 18 - ________________________________HELLO__________________________________
00:32:14 - main - WARNING - <module>: 18 - ________________________________HELLO__________________________________
00:32:12 - main - WARNING - <module>: 18 - ________________________________HELLO__________________________________
00:31:45 - main - WARNING - <module>: 18 - ________________________________HELLO__________________________________
00:31:51 - main - WARNING - <module>: 18 - ________________________________HELLO__________________________________
00:34:51 - main - WARNING - <module>: 18 - ________________________________HELLO__________________________________
00:33:30 - main - WARNING - <module>: 18 - ________________________________HELLO__________________________________
00:31:36 - main - WARNING - <module>: 18 - ________________________________HELLO__________________________________
00:31:58 - main - WARNING - <module>: 18 - ________________________________HELLO__________________________________
00:32:08 - main - WARNING - <module>: 18 - ________________________________HELLO__________________________________
00:31:59 - main - WARNING - <module>: 18 - ________________________________HELLO__________________________________
00:30:23 - main - WARNING - <module>: 18 - ________________________________HELLO__________________________________
00:35:09 - main - WARNING - <module>: 18 - ________________________________HELLO__________________________________
00:33:50 - main - WARNING - <module>: 18 - ________________________________HELLO__________________________________
00:32:10 - main - WARNING - <module>: 18 - ________________________________HELLO__________________________________
00:31:20 - main - WARNING - <module>: 18 - ________________________________HELLO__________________________________
00:32:10 - main - WARNING - <module>: 18 - ________________________________HELLO__________________________________
00:36:25 - main - WARNING - <module>: 18 - ________________________________HELLO__________________________________
00:31:23 - main - WARNING - <module>: 18 - ________________________________HELLO__________________________________
00:34:23 - main - WARNING - <module>: 18 - ________________________________HELLO__________________________________
00:33:06 - main - WARNING - <module>: 18 - ________________________________HELLO__________________________________
00:31:36 - main - WARNING - <module>: 18 - ________________________________HELLO__________________________________
00:32:41 - main - WARNING - <module>: 18 - ________________________________HELLO__________________________________
00:26:32 - main - WARNING - <module>: 18 - ________________________________HELLO__________________________________
00:32:25 - main - WARNING - <module>: 18 - ________________________________HELLO__________________________________
00:31:15 - main - WARNING - <module>: 18 - ________________________________HELLO__________________________________
00:35:09 - main - WARNING - <module>: 18 - ________________________________HELLO__________________________________
00:33:41 - main - WARNING - <module>: 18 - ________________________________HELLO__________________________________
00:31:44 - main - WARNING - <module>: 18 - ________________________________HELLO__________________________________
00:32:14 - main - WARNING - <module>: 18 - ________________________________HELLO__________________________________
00:31:51 - main - WARNING - <module>: 18 - ________________________________HELLO__________________________________
00:32:08 - main - WARNING - <module>: 18 - ________________________________HELLO__________________________________
00:31:03 - main - WARNING - <module>: 18 - ________________________________HELLO__________________________________
00:35:05 - main - WARNING - <module>: 18 - ________________________________HELLO__________________________________
00:33:46 - main - WARNING - <module>: 18 - ________________________________HELLO__________________________________
00:32:21 - main - WARNING - <module>: 18 - ________________________________HELLO__________________________________
00:32:22 - main - WARNING - <module>: 18 - ________________________________HELLO__________________________________
00:33:51 - main - WARNING - <module>: 18 - ________________________________HELLO__________________________________
00:32:06 - main - WARNING - <module>: 18 - ________________________________HELLO__________________________________
00:31:38 - main - WARNING - <module>: 18 - ________________________________HELLO__________________________________
00:36:02 - main - WARNING - <module>: 18 - ________________________________HELLO__________________________________
00:34:07 - main - WARNING - <module>: 18 - ________________________________HELLO__________________________________
00:32:19 - main - WARNING - <module>: 18 - ________________________________HELLO__________________________________
00:32:10 - main - WARNING - <module>: 18 - ________________________________HELLO__________________________________
00:32:37 - main - WARNING - <module>: 18 - ________________________________HELLO__________________________________
00:33:07 - main - WARNING - sending: 197 - cannot write empty image as JPEG
00:33:30 - main - ERROR - <module>: 240 - A request to the Telegram API was unsuccessful. Error code: 429. Description: Too Many Requests: retry after 24
Traceback (most recent call last):
  File "/home/runner/work/FortDaily-PVE_bot/FortDaily-PVE_bot/main.py", line 193, in sending
    bot.send_photo(chat_id=channel_id, photo=page)
  File "/opt/hostedtoolcache/Python/3.9.19/x64/lib/python3.9/site-packages/telebot/__init__.py", line 1825, in send_photo
    apihelper.send_photo(
  File "/opt/hostedtoolcache/Python/3.9.19/x64/lib/python3.9/site-packages/telebot/apihelper.py", line 469, in send_photo
    files = {'photo': util.pil_image_to_file(photo)}
  File "/opt/hostedtoolcache/Python/3.9.19/x64/lib/python3.9/site-packages/telebot/service_utils.py", line 62, in pil_image_to_file
    image.convert('RGB').save(photoBuffer, extension, quality=quality)
  File "/opt/hostedtoolcache/Python/3.9.19/x64/lib/python3.9/site-packages/PIL/Image.py", line 2432, in save
    save_handler(self, fp, filename)
  File "/opt/hostedtoolcache/Python/3.9.19/x64/lib/python3.9/site-packages/PIL/JpegImagePlugin.py", line 637, in _save
    raise ValueError(msg)
ValueError: cannot write empty image as JPEG

During handling of the above exception, another exception occurred:

Traceback (most recent call last):
  File "/home/runner/work/FortDaily-PVE_bot/FortDaily-PVE_bot/main.py", line 206, in sending
    bot.send_photo(chat_id=channel_id, photo=page)
  File "/opt/hostedtoolcache/Python/3.9.19/x64/lib/python3.9/site-packages/telebot/__init__.py", line 1825, in send_photo
    apihelper.send_photo(
  File "/opt/hostedtoolcache/Python/3.9.19/x64/lib/python3.9/site-packages/telebot/apihelper.py", line 494, in send_photo
    return _make_request(token, method_url, params=payload, files=files, method='post')
  File "/opt/hostedtoolcache/Python/3.9.19/x64/lib/python3.9/site-packages/telebot/apihelper.py", line 162, in _make_request
    json_result = _check_result(method_name, result)
  File "/opt/hostedtoolcache/Python/3.9.19/x64/lib/python3.9/site-packages/telebot/apihelper.py", line 189, in _check_result
    raise ApiTelegramException(method_name, result, result_json)
telebot.apihelper.ApiTelegramException: A request to the Telegram API was unsuccessful. Error code: 429. Description: Too Many Requests: retry after 25

During handling of the above exception, another exception occurred:

Traceback (most recent call last):
  File "/home/runner/work/FortDaily-PVE_bot/FortDaily-PVE_bot/main.py", line 238, in <module>
    sending()
  File "/home/runner/work/FortDaily-PVE_bot/FortDaily-PVE_bot/main.py", line 211, in sending
    bot.send_message(chat_id=channel_id, text='<u>Сегодня нет V-Bucks</u>')
  File "/opt/hostedtoolcache/Python/3.9.19/x64/lib/python3.9/site-packages/telebot/__init__.py", line 1549, in send_message
    apihelper.send_message(
  File "/opt/hostedtoolcache/Python/3.9.19/x64/lib/python3.9/site-packages/telebot/apihelper.py", line 264, in send_message
    return _make_request(token, method_url, params=payload, method='post')
  File "/opt/hostedtoolcache/Python/3.9.19/x64/lib/python3.9/site-packages/telebot/apihelper.py", line 162, in _make_request
    json_result = _check_result(method_name, result)
  File "/opt/hostedtoolcache/Python/3.9.19/x64/lib/python3.9/site-packages/telebot/apihelper.py", line 189, in _check_result
    raise ApiTelegramException(method_name, result, result_json)
telebot.apihelper.ApiTelegramException: A request to the Telegram API was unsuccessful. Error code: 429. Description: Too Many Requests: retry after 24
00:32:32 - main - WARNING - <module>: 18 - ________________________________HELLO__________________________________
00:33:01 - main - WARNING - sending: 197 - cannot write empty image as JPEG
00:33:23 - main - ERROR - <module>: 240 - A request to the Telegram API was unsuccessful. Error code: 429. Description: Too Many Requests: retry after 25
Traceback (most recent call last):
  File "/home/runner/work/FortDaily-PVE_bot/FortDaily-PVE_bot/main.py", line 193, in sending
    bot.send_photo(chat_id=channel_id, photo=page)
  File "/opt/hostedtoolcache/Python/3.9.19/x64/lib/python3.9/site-packages/telebot/__init__.py", line 1825, in send_photo
    apihelper.send_photo(
  File "/opt/hostedtoolcache/Python/3.9.19/x64/lib/python3.9/site-packages/telebot/apihelper.py", line 469, in send_photo
    files = {'photo': util.pil_image_to_file(photo)}
  File "/opt/hostedtoolcache/Python/3.9.19/x64/lib/python3.9/site-packages/telebot/service_utils.py", line 62, in pil_image_to_file
    image.convert('RGB').save(photoBuffer, extension, quality=quality)
  File "/opt/hostedtoolcache/Python/3.9.19/x64/lib/python3.9/site-packages/PIL/Image.py", line 2432, in save
    save_handler(self, fp, filename)
  File "/opt/hostedtoolcache/Python/3.9.19/x64/lib/python3.9/site-packages/PIL/JpegImagePlugin.py", line 637, in _save
    raise ValueError(msg)
ValueError: cannot write empty image as JPEG

During handling of the above exception, another exception occurred:

Traceback (most recent call last):
  File "/home/runner/work/FortDaily-PVE_bot/FortDaily-PVE_bot/main.py", line 206, in sending
    bot.send_photo(chat_id=channel_id, photo=page)
  File "/opt/hostedtoolcache/Python/3.9.19/x64/lib/python3.9/site-packages/telebot/__init__.py", line 1825, in send_photo
    apihelper.send_photo(
  File "/opt/hostedtoolcache/Python/3.9.19/x64/lib/python3.9/site-packages/telebot/apihelper.py", line 494, in send_photo
    return _make_request(token, method_url, params=payload, files=files, method='post')
  File "/opt/hostedtoolcache/Python/3.9.19/x64/lib/python3.9/site-packages/telebot/apihelper.py", line 162, in _make_request
    json_result = _check_result(method_name, result)
  File "/opt/hostedtoolcache/Python/3.9.19/x64/lib/python3.9/site-packages/telebot/apihelper.py", line 189, in _check_result
    raise ApiTelegramException(method_name, result, result_json)
telebot.apihelper.ApiTelegramException: A request to the Telegram API was unsuccessful. Error code: 429. Description: Too Many Requests: retry after 26

During handling of the above exception, another exception occurred:

Traceback (most recent call last):
  File "/home/runner/work/FortDaily-PVE_bot/FortDaily-PVE_bot/main.py", line 238, in <module>
    sending()
  File "/home/runner/work/FortDaily-PVE_bot/FortDaily-PVE_bot/main.py", line 213, in sending
    bot.send_message(chat_id=channel_id, text=alerts)
  File "/opt/hostedtoolcache/Python/3.9.19/x64/lib/python3.9/site-packages/telebot/__init__.py", line 1549, in send_message
    apihelper.send_message(
  File "/opt/hostedtoolcache/Python/3.9.19/x64/lib/python3.9/site-packages/telebot/apihelper.py", line 264, in send_message
    return _make_request(token, method_url, params=payload, method='post')
  File "/opt/hostedtoolcache/Python/3.9.19/x64/lib/python3.9/site-packages/telebot/apihelper.py", line 162, in _make_request
    json_result = _check_result(method_name, result)
  File "/opt/hostedtoolcache/Python/3.9.19/x64/lib/python3.9/site-packages/telebot/apihelper.py", line 189, in _check_result
    raise ApiTelegramException(method_name, result, result_json)
telebot.apihelper.ApiTelegramException: A request to the Telegram API was unsuccessful. Error code: 429. Description: Too Many Requests: retry after 25
00:31:29 - main - WARNING - <module>: 18 - ________________________________HELLO__________________________________
00:31:46 - main - WARNING - sending: 197 - cannot write empty image as JPEG
00:32:01 - main - ERROR - <module>: 240 - cannot write empty image as JPEG
Traceback (most recent call last):
  File "/home/runner/work/FortDaily-PVE_bot/FortDaily-PVE_bot/main.py", line 193, in sending
    bot.send_photo(chat_id=channel_id, photo=page)
  File "/opt/hostedtoolcache/Python/3.9.19/x64/lib/python3.9/site-packages/telebot/__init__.py", line 1825, in send_photo
    apihelper.send_photo(
  File "/opt/hostedtoolcache/Python/3.9.19/x64/lib/python3.9/site-packages/telebot/apihelper.py", line 469, in send_photo
    files = {'photo': util.pil_image_to_file(photo)}
  File "/opt/hostedtoolcache/Python/3.9.19/x64/lib/python3.9/site-packages/telebot/service_utils.py", line 62, in pil_image_to_file
    image.convert('RGB').save(photoBuffer, extension, quality=quality)
  File "/opt/hostedtoolcache/Python/3.9.19/x64/lib/python3.9/site-packages/PIL/Image.py", line 2432, in save
    save_handler(self, fp, filename)
  File "/opt/hostedtoolcache/Python/3.9.19/x64/lib/python3.9/site-packages/PIL/JpegImagePlugin.py", line 637, in _save
    raise ValueError(msg)
ValueError: cannot write empty image as JPEG

During handling of the above exception, another exception occurred:

Traceback (most recent call last):
  File "/home/runner/work/FortDaily-PVE_bot/FortDaily-PVE_bot/main.py", line 238, in <module>
    sending()
  File "/home/runner/work/FortDaily-PVE_bot/FortDaily-PVE_bot/main.py", line 206, in sending
    bot.send_photo(chat_id=channel_id, photo=page)
  File "/opt/hostedtoolcache/Python/3.9.19/x64/lib/python3.9/site-packages/telebot/__init__.py", line 1825, in send_photo
    apihelper.send_photo(
  File "/opt/hostedtoolcache/Python/3.9.19/x64/lib/python3.9/site-packages/telebot/apihelper.py", line 469, in send_photo
    files = {'photo': util.pil_image_to_file(photo)}
  File "/opt/hostedtoolcache/Python/3.9.19/x64/lib/python3.9/site-packages/telebot/service_utils.py", line 62, in pil_image_to_file
    image.convert('RGB').save(photoBuffer, extension, quality=quality)
  File "/opt/hostedtoolcache/Python/3.9.19/x64/lib/python3.9/site-packages/PIL/Image.py", line 2432, in save
    save_handler(self, fp, filename)
  File "/opt/hostedtoolcache/Python/3.9.19/x64/lib/python3.9/site-packages/PIL/JpegImagePlugin.py", line 637, in _save
    raise ValueError(msg)
ValueError: cannot write empty image as JPEG
00:36:45 - main - WARNING - <module>: 18 - ________________________________HELLO__________________________________
00:37:03 - main - WARNING - sending: 197 - cannot write empty image as JPEG
00:37:21 - main - ERROR - <module>: 240 - cannot write empty image as JPEG
Traceback (most recent call last):
  File "/home/runner/work/FortDaily-PVE_bot/FortDaily-PVE_bot/main.py", line 193, in sending
    bot.send_photo(chat_id=channel_id, photo=page)
  File "/opt/hostedtoolcache/Python/3.9.19/x64/lib/python3.9/site-packages/telebot/__init__.py", line 1825, in send_photo
    apihelper.send_photo(
  File "/opt/hostedtoolcache/Python/3.9.19/x64/lib/python3.9/site-packages/telebot/apihelper.py", line 469, in send_photo
    files = {'photo': util.pil_image_to_file(photo)}
  File "/opt/hostedtoolcache/Python/3.9.19/x64/lib/python3.9/site-packages/telebot/service_utils.py", line 62, in pil_image_to_file
    image.convert('RGB').save(photoBuffer, extension, quality=quality)
  File "/opt/hostedtoolcache/Python/3.9.19/x64/lib/python3.9/site-packages/PIL/Image.py", line 2432, in save
    save_handler(self, fp, filename)
  File "/opt/hostedtoolcache/Python/3.9.19/x64/lib/python3.9/site-packages/PIL/JpegImagePlugin.py", line 637, in _save
    raise ValueError(msg)
ValueError: cannot write empty image as JPEG

During handling of the above exception, another exception occurred:

Traceback (most recent call last):
  File "/home/runner/work/FortDaily-PVE_bot/FortDaily-PVE_bot/main.py", line 238, in <module>
    sending()
  File "/home/runner/work/FortDaily-PVE_bot/FortDaily-PVE_bot/main.py", line 206, in sending
    bot.send_photo(chat_id=channel_id, photo=page)
  File "/opt/hostedtoolcache/Python/3.9.19/x64/lib/python3.9/site-packages/telebot/__init__.py", line 1825, in send_photo
    apihelper.send_photo(
  File "/opt/hostedtoolcache/Python/3.9.19/x64/lib/python3.9/site-packages/telebot/apihelper.py", line 469, in send_photo
    files = {'photo': util.pil_image_to_file(photo)}
  File "/opt/hostedtoolcache/Python/3.9.19/x64/lib/python3.9/site-packages/telebot/service_utils.py", line 62, in pil_image_to_file
    image.convert('RGB').save(photoBuffer, extension, quality=quality)
  File "/opt/hostedtoolcache/Python/3.9.19/x64/lib/python3.9/site-packages/PIL/Image.py", line 2432, in save
    save_handler(self, fp, filename)
  File "/opt/hostedtoolcache/Python/3.9.19/x64/lib/python3.9/site-packages/PIL/JpegImagePlugin.py", line 637, in _save
    raise ValueError(msg)
ValueError: cannot write empty image as JPEG
00:36:55 - main - WARNING - <module>: 18 - ________________________________HELLO__________________________________
00:33:10 - main - WARNING - <module>: 18 - ________________________________HELLO__________________________________
00:32:27 - main - WARNING - <module>: 18 - ________________________________HELLO__________________________________
00:33:55 - main - WARNING - <module>: 18 - ________________________________HELLO__________________________________
00:33:37 - main - WARNING - <module>: 18 - ________________________________HELLO__________________________________
00:32:15 - main - WARNING - <module>: 18 - ________________________________HELLO__________________________________
00:37:11 - main - WARNING - <module>: 18 - ________________________________HELLO__________________________________
00:34:26 - main - WARNING - <module>: 18 - ________________________________HELLO__________________________________
00:33:34 - main - WARNING - <module>: 18 - ________________________________HELLO__________________________________
