00:40:14 - main - WARNING - <module>: 18 - ________________________________HELLO__________________________________
00:43:20 - main - WARNING - <module>: 18 - ________________________________HELLO__________________________________
00:44:02 - main - WARNING - <module>: 18 - ________________________________HELLO__________________________________
00:44:03 - main - WARNING - sending: 194 - cannot write empty image as JPEG
00:44:03 - main - ERROR - <module>: 234 - cannot write empty image as JPEG
Traceback (most recent call last):
  File "/home/runner/work/FortDaily-PVE_bot/FortDaily-PVE_bot/main.py", line 191, in sending
    bot.send_photo(chat_id=channel_id, photo=page)
  File "/opt/hostedtoolcache/Python/3.9.17/x64/lib/python3.9/site-packages/telebot/__init__.py", line 1825, in send_photo
    apihelper.send_photo(
  File "/opt/hostedtoolcache/Python/3.9.17/x64/lib/python3.9/site-packages/telebot/apihelper.py", line 469, in send_photo
    files = {'photo': util.pil_image_to_file(photo)}
  File "/opt/hostedtoolcache/Python/3.9.17/x64/lib/python3.9/site-packages/telebot/service_utils.py", line 62, in pil_image_to_file
    image.convert('RGB').save(photoBuffer, extension, quality=quality)
  File "/opt/hostedtoolcache/Python/3.9.17/x64/lib/python3.9/site-packages/PIL/Image.py", line 2432, in save
    save_handler(self, fp, filename)
  File "/opt/hostedtoolcache/Python/3.9.17/x64/lib/python3.9/site-packages/PIL/JpegImagePlugin.py", line 637, in _save
    raise ValueError(msg)
ValueError: cannot write empty image as JPEG

During handling of the above exception, another exception occurred:

Traceback (most recent call last):
  File "/home/runner/work/FortDaily-PVE_bot/FortDaily-PVE_bot/main.py", line 232, in <module>
    sending()
  File "/home/runner/work/FortDaily-PVE_bot/FortDaily-PVE_bot/main.py", line 201, in sending
    bot.send_photo(chat_id=channel_id, photo=page)
  File "/opt/hostedtoolcache/Python/3.9.17/x64/lib/python3.9/site-packages/telebot/__init__.py", line 1825, in send_photo
    apihelper.send_photo(
  File "/opt/hostedtoolcache/Python/3.9.17/x64/lib/python3.9/site-packages/telebot/apihelper.py", line 469, in send_photo
    files = {'photo': util.pil_image_to_file(photo)}
  File "/opt/hostedtoolcache/Python/3.9.17/x64/lib/python3.9/site-packages/telebot/service_utils.py", line 62, in pil_image_to_file
    image.convert('RGB').save(photoBuffer, extension, quality=quality)
  File "/opt/hostedtoolcache/Python/3.9.17/x64/lib/python3.9/site-packages/PIL/Image.py", line 2432, in save
    save_handler(self, fp, filename)
  File "/opt/hostedtoolcache/Python/3.9.17/x64/lib/python3.9/site-packages/PIL/JpegImagePlugin.py", line 637, in _save
    raise ValueError(msg)
ValueError: cannot write empty image as JPEG
00:48:45 - main - WARNING - <module>: 18 - ________________________________HELLO__________________________________
00:44:48 - main - WARNING - <module>: 18 - ________________________________HELLO__________________________________
00:44:10 - main - WARNING - <module>: 18 - ________________________________HELLO__________________________________
00:44:31 - main - WARNING - <module>: 18 - ________________________________HELLO__________________________________
00:43:13 - main - WARNING - <module>: 18 - ________________________________HELLO__________________________________
00:42:04 - main - WARNING - <module>: 18 - ________________________________HELLO__________________________________
00:48:59 - main - WARNING - <module>: 18 - ________________________________HELLO__________________________________
00:46:36 - main - WARNING - <module>: 18 - ________________________________HELLO__________________________________
00:44:34 - main - WARNING - <module>: 18 - ________________________________HELLO__________________________________
00:44:52 - main - WARNING - <module>: 18 - ________________________________HELLO__________________________________
00:44:49 - main - WARNING - <module>: 18 - ________________________________HELLO__________________________________
00:45:28 - main - WARNING - <module>: 18 - ________________________________HELLO__________________________________
00:48:45 - main - WARNING - <module>: 18 - ________________________________HELLO__________________________________
00:43:45 - main - WARNING - <module>: 18 - ________________________________HELLO__________________________________
00:49:05 - main - WARNING - <module>: 18 - ________________________________HELLO__________________________________
00:44:44 - main - WARNING - <module>: 18 - ________________________________HELLO__________________________________
00:39:36 - main - WARNING - <module>: 18 - ________________________________HELLO__________________________________
00:45:08 - main - WARNING - <module>: 18 - ________________________________HELLO__________________________________
00:45:03 - main - WARNING - <module>: 18 - ________________________________HELLO__________________________________
00:44:50 - main - WARNING - <module>: 18 - ________________________________HELLO__________________________________
00:43:35 - main - WARNING - <module>: 18 - ________________________________HELLO__________________________________
00:43:36 - main - WARNING - sending: 194 - cannot write empty image as JPEG
00:43:36 - main - ERROR - <module>: 234 - cannot write empty image as JPEG
Traceback (most recent call last):
  File "/home/runner/work/FortDaily-PVE_bot/FortDaily-PVE_bot/main.py", line 191, in sending
    bot.send_photo(chat_id=channel_id, photo=page)
  File "/opt/hostedtoolcache/Python/3.9.17/x64/lib/python3.9/site-packages/telebot/__init__.py", line 1825, in send_photo
    apihelper.send_photo(
  File "/opt/hostedtoolcache/Python/3.9.17/x64/lib/python3.9/site-packages/telebot/apihelper.py", line 469, in send_photo
    files = {'photo': util.pil_image_to_file(photo)}
  File "/opt/hostedtoolcache/Python/3.9.17/x64/lib/python3.9/site-packages/telebot/service_utils.py", line 62, in pil_image_to_file
    image.convert('RGB').save(photoBuffer, extension, quality=quality)
  File "/opt/hostedtoolcache/Python/3.9.17/x64/lib/python3.9/site-packages/PIL/Image.py", line 2432, in save
    save_handler(self, fp, filename)
  File "/opt/hostedtoolcache/Python/3.9.17/x64/lib/python3.9/site-packages/PIL/JpegImagePlugin.py", line 637, in _save
    raise ValueError(msg)
ValueError: cannot write empty image as JPEG

During handling of the above exception, another exception occurred:

Traceback (most recent call last):
  File "/home/runner/work/FortDaily-PVE_bot/FortDaily-PVE_bot/main.py", line 232, in <module>
    sending()
  File "/home/runner/work/FortDaily-PVE_bot/FortDaily-PVE_bot/main.py", line 201, in sending
    bot.send_photo(chat_id=channel_id, photo=page)
  File "/opt/hostedtoolcache/Python/3.9.17/x64/lib/python3.9/site-packages/telebot/__init__.py", line 1825, in send_photo
    apihelper.send_photo(
  File "/opt/hostedtoolcache/Python/3.9.17/x64/lib/python3.9/site-packages/telebot/apihelper.py", line 469, in send_photo
    files = {'photo': util.pil_image_to_file(photo)}
  File "/opt/hostedtoolcache/Python/3.9.17/x64/lib/python3.9/site-packages/telebot/service_utils.py", line 62, in pil_image_to_file
    image.convert('RGB').save(photoBuffer, extension, quality=quality)
  File "/opt/hostedtoolcache/Python/3.9.17/x64/lib/python3.9/site-packages/PIL/Image.py", line 2432, in save
    save_handler(self, fp, filename)
  File "/opt/hostedtoolcache/Python/3.9.17/x64/lib/python3.9/site-packages/PIL/JpegImagePlugin.py", line 637, in _save
    raise ValueError(msg)
ValueError: cannot write empty image as JPEG
00:51:16 - main - WARNING - <module>: 18 - ________________________________HELLO__________________________________
00:47:43 - main - WARNING - <module>: 18 - ________________________________HELLO__________________________________
00:48:10 - main - WARNING - sending: 194 - A request to the Telegram API was unsuccessful. Error code: 400. Description: Bad Request: failed to send message #7 with the error message "PHOTO_INVALID_DIMENSIONS"
00:48:36 - main - ERROR - <module>: 234 - A request to the Telegram API was unsuccessful. Error code: 400. Description: Bad Request: failed to send message #8 with the error message "PHOTO_INVALID_DIMENSIONS"
Traceback (most recent call last):
  File "/home/runner/work/FortDaily-PVE_bot/FortDaily-PVE_bot/main.py", line 188, in sending
    bot.send_media_group(chat_id=channel_id, media=mediagroup)
  File "/opt/hostedtoolcache/Python/3.9.17/x64/lib/python3.9/site-packages/telebot/__init__.py", line 2523, in send_media_group
    result = apihelper.send_media_group(
  File "/opt/hostedtoolcache/Python/3.9.17/x64/lib/python3.9/site-packages/telebot/apihelper.py", line 516, in send_media_group
    return _make_request(
  File "/opt/hostedtoolcache/Python/3.9.17/x64/lib/python3.9/site-packages/telebot/apihelper.py", line 162, in _make_request
    json_result = _check_result(method_name, result)
  File "/opt/hostedtoolcache/Python/3.9.17/x64/lib/python3.9/site-packages/telebot/apihelper.py", line 189, in _check_result
    raise ApiTelegramException(method_name, result, result_json)
telebot.apihelper.ApiTelegramException: A request to the Telegram API was unsuccessful. Error code: 400. Description: Bad Request: failed to send message #7 with the error message "PHOTO_INVALID_DIMENSIONS"

During handling of the above exception, another exception occurred:

Traceback (most recent call last):
  File "/home/runner/work/FortDaily-PVE_bot/FortDaily-PVE_bot/main.py", line 232, in <module>
    sending()
  File "/home/runner/work/FortDaily-PVE_bot/FortDaily-PVE_bot/main.py", line 198, in sending
    bot.send_media_group(chat_id=channel_id, media=mediagroup)
  File "/opt/hostedtoolcache/Python/3.9.17/x64/lib/python3.9/site-packages/telebot/__init__.py", line 2523, in send_media_group
    result = apihelper.send_media_group(
  File "/opt/hostedtoolcache/Python/3.9.17/x64/lib/python3.9/site-packages/telebot/apihelper.py", line 516, in send_media_group
    return _make_request(
  File "/opt/hostedtoolcache/Python/3.9.17/x64/lib/python3.9/site-packages/telebot/apihelper.py", line 162, in _make_request
    json_result = _check_result(method_name, result)
  File "/opt/hostedtoolcache/Python/3.9.17/x64/lib/python3.9/site-packages/telebot/apihelper.py", line 189, in _check_result
    raise ApiTelegramException(method_name, result, result_json)
telebot.apihelper.ApiTelegramException: A request to the Telegram API was unsuccessful. Error code: 400. Description: Bad Request: failed to send message #8 with the error message "PHOTO_INVALID_DIMENSIONS"
01:02:41 - main - WARNING - <module>: 18 - ________________________________HELLO__________________________________
01:03:02 - main - WARNING - sending: 194 - A request to the Telegram API was unsuccessful. Error code: 400. Description: Bad Request: failed to send message #6 with the error message "PHOTO_INVALID_DIMENSIONS"
01:03:21 - main - ERROR - <module>: 234 - A request to the Telegram API was unsuccessful. Error code: 400. Description: Bad Request: failed to send message #6 with the error message "PHOTO_INVALID_DIMENSIONS"
Traceback (most recent call last):
  File "/home/runner/work/FortDaily-PVE_bot/FortDaily-PVE_bot/main.py", line 188, in sending
    bot.send_media_group(chat_id=channel_id, media=mediagroup)
  File "/opt/hostedtoolcache/Python/3.9.17/x64/lib/python3.9/site-packages/telebot/__init__.py", line 2523, in send_media_group
    result = apihelper.send_media_group(
  File "/opt/hostedtoolcache/Python/3.9.17/x64/lib/python3.9/site-packages/telebot/apihelper.py", line 516, in send_media_group
    return _make_request(
  File "/opt/hostedtoolcache/Python/3.9.17/x64/lib/python3.9/site-packages/telebot/apihelper.py", line 162, in _make_request
    json_result = _check_result(method_name, result)
  File "/opt/hostedtoolcache/Python/3.9.17/x64/lib/python3.9/site-packages/telebot/apihelper.py", line 189, in _check_result
    raise ApiTelegramException(method_name, result, result_json)
telebot.apihelper.ApiTelegramException: A request to the Telegram API was unsuccessful. Error code: 400. Description: Bad Request: failed to send message #6 with the error message "PHOTO_INVALID_DIMENSIONS"

During handling of the above exception, another exception occurred:

Traceback (most recent call last):
  File "/home/runner/work/FortDaily-PVE_bot/FortDaily-PVE_bot/main.py", line 232, in <module>
    sending()
  File "/home/runner/work/FortDaily-PVE_bot/FortDaily-PVE_bot/main.py", line 198, in sending
    bot.send_media_group(chat_id=channel_id, media=mediagroup)
  File "/opt/hostedtoolcache/Python/3.9.17/x64/lib/python3.9/site-packages/telebot/__init__.py", line 2523, in send_media_group
    result = apihelper.send_media_group(
  File "/opt/hostedtoolcache/Python/3.9.17/x64/lib/python3.9/site-packages/telebot/apihelper.py", line 516, in send_media_group
    return _make_request(
  File "/opt/hostedtoolcache/Python/3.9.17/x64/lib/python3.9/site-packages/telebot/apihelper.py", line 162, in _make_request
    json_result = _check_result(method_name, result)
  File "/opt/hostedtoolcache/Python/3.9.17/x64/lib/python3.9/site-packages/telebot/apihelper.py", line 189, in _check_result
    raise ApiTelegramException(method_name, result, result_json)
telebot.apihelper.ApiTelegramException: A request to the Telegram API was unsuccessful. Error code: 400. Description: Bad Request: failed to send message #6 with the error message "PHOTO_INVALID_DIMENSIONS"
01:08:58 - main - WARNING - <module>: 18 - ________________________________HELLO__________________________________
01:09:27 - main - WARNING - sending: 194 - A request to the Telegram API was unsuccessful. Error code: 400. Description: Bad Request: failed to send message #1 with the error message "PHOTO_INVALID_DIMENSIONS"
01:09:54 - main - ERROR - <module>: 234 - A request to the Telegram API was unsuccessful. Error code: 400. Description: Bad Request: failed to send message #1 with the error message "PHOTO_INVALID_DIMENSIONS"
Traceback (most recent call last):
  File "/home/runner/work/FortDaily-PVE_bot/FortDaily-PVE_bot/main.py", line 188, in sending
    bot.send_media_group(chat_id=channel_id, media=mediagroup)
  File "/opt/hostedtoolcache/Python/3.9.17/x64/lib/python3.9/site-packages/telebot/__init__.py", line 2523, in send_media_group
    result = apihelper.send_media_group(
  File "/opt/hostedtoolcache/Python/3.9.17/x64/lib/python3.9/site-packages/telebot/apihelper.py", line 516, in send_media_group
    return _make_request(
  File "/opt/hostedtoolcache/Python/3.9.17/x64/lib/python3.9/site-packages/telebot/apihelper.py", line 162, in _make_request
    json_result = _check_result(method_name, result)
  File "/opt/hostedtoolcache/Python/3.9.17/x64/lib/python3.9/site-packages/telebot/apihelper.py", line 189, in _check_result
    raise ApiTelegramException(method_name, result, result_json)
telebot.apihelper.ApiTelegramException: A request to the Telegram API was unsuccessful. Error code: 400. Description: Bad Request: failed to send message #1 with the error message "PHOTO_INVALID_DIMENSIONS"

During handling of the above exception, another exception occurred:

Traceback (most recent call last):
  File "/home/runner/work/FortDaily-PVE_bot/FortDaily-PVE_bot/main.py", line 232, in <module>
    sending()
  File "/home/runner/work/FortDaily-PVE_bot/FortDaily-PVE_bot/main.py", line 198, in sending
    bot.send_media_group(chat_id=channel_id, media=mediagroup)
  File "/opt/hostedtoolcache/Python/3.9.17/x64/lib/python3.9/site-packages/telebot/__init__.py", line 2523, in send_media_group
    result = apihelper.send_media_group(
  File "/opt/hostedtoolcache/Python/3.9.17/x64/lib/python3.9/site-packages/telebot/apihelper.py", line 516, in send_media_group
    return _make_request(
  File "/opt/hostedtoolcache/Python/3.9.17/x64/lib/python3.9/site-packages/telebot/apihelper.py", line 162, in _make_request
    json_result = _check_result(method_name, result)
  File "/opt/hostedtoolcache/Python/3.9.17/x64/lib/python3.9/site-packages/telebot/apihelper.py", line 189, in _check_result
    raise ApiTelegramException(method_name, result, result_json)
telebot.apihelper.ApiTelegramException: A request to the Telegram API was unsuccessful. Error code: 400. Description: Bad Request: failed to send message #1 with the error message "PHOTO_INVALID_DIMENSIONS"
