00:30:15 - main - WARNING - <module>: 18 - ________________________________HELLO__________________________________
00:30:15 - main - WARNING - sending: 194 - cannot write empty image as JPEG
00:30:16 - main - ERROR - <module>: 234 - cannot write empty image as JPEG
Traceback (most recent call last):
  File "/home/runner/work/FortDaily-PVE_bot/FortDaily-PVE_bot/main.py", line 191, in sending
    bot.send_photo(chat_id=channel_id, photo=page)
  File "/opt/hostedtoolcache/Python/3.9.17/x64/lib/python3.9/site-packages/telebot/__init__.py", line 1825, in send_photo
    apihelper.send_photo(
  File "/opt/hostedtoolcache/Python/3.9.17/x64/lib/python3.9/site-packages/telebot/apihelper.py", line 469, in send_photo
    files = {'photo': util.pil_image_to_file(photo)}
  File "/opt/hostedtoolcache/Python/3.9.17/x64/lib/python3.9/site-packages/telebot/service_utils.py", line 62, in pil_image_to_file
    image.convert('RGB').save(photoBuffer, extension, quality=quality)
  File "/opt/hostedtoolcache/Python/3.9.17/x64/lib/python3.9/site-packages/PIL/Image.py", line 2432, in save
    save_handler(self, fp, filename)
  File "/opt/hostedtoolcache/Python/3.9.17/x64/lib/python3.9/site-packages/PIL/JpegImagePlugin.py", line 637, in _save
    raise ValueError(msg)
ValueError: cannot write empty image as JPEG

During handling of the above exception, another exception occurred:

Traceback (most recent call last):
  File "/home/runner/work/FortDaily-PVE_bot/FortDaily-PVE_bot/main.py", line 232, in <module>
    sending()
  File "/home/runner/work/FortDaily-PVE_bot/FortDaily-PVE_bot/main.py", line 201, in sending
    bot.send_photo(chat_id=channel_id, photo=page)
  File "/opt/hostedtoolcache/Python/3.9.17/x64/lib/python3.9/site-packages/telebot/__init__.py", line 1825, in send_photo
    apihelper.send_photo(
  File "/opt/hostedtoolcache/Python/3.9.17/x64/lib/python3.9/site-packages/telebot/apihelper.py", line 469, in send_photo
    files = {'photo': util.pil_image_to_file(photo)}
  File "/opt/hostedtoolcache/Python/3.9.17/x64/lib/python3.9/site-packages/telebot/service_utils.py", line 62, in pil_image_to_file
    image.convert('RGB').save(photoBuffer, extension, quality=quality)
  File "/opt/hostedtoolcache/Python/3.9.17/x64/lib/python3.9/site-packages/PIL/Image.py", line 2432, in save
    save_handler(self, fp, filename)
  File "/opt/hostedtoolcache/Python/3.9.17/x64/lib/python3.9/site-packages/PIL/JpegImagePlugin.py", line 637, in _save
    raise ValueError(msg)
ValueError: cannot write empty image as JPEG
00:30:18 - main - WARNING - <module>: 18 - ________________________________HELLO__________________________________
00:30:19 - main - WARNING - sending: 194 - cannot write empty image as JPEG
00:30:19 - main - ERROR - <module>: 234 - cannot write empty image as JPEG
Traceback (most recent call last):
  File "/home/runner/work/FortDaily-PVE_bot/FortDaily-PVE_bot/main.py", line 191, in sending
    bot.send_photo(chat_id=channel_id, photo=page)
  File "/opt/hostedtoolcache/Python/3.9.17/x64/lib/python3.9/site-packages/telebot/__init__.py", line 1825, in send_photo
    apihelper.send_photo(
  File "/opt/hostedtoolcache/Python/3.9.17/x64/lib/python3.9/site-packages/telebot/apihelper.py", line 469, in send_photo
    files = {'photo': util.pil_image_to_file(photo)}
  File "/opt/hostedtoolcache/Python/3.9.17/x64/lib/python3.9/site-packages/telebot/service_utils.py", line 62, in pil_image_to_file
    image.convert('RGB').save(photoBuffer, extension, quality=quality)
  File "/opt/hostedtoolcache/Python/3.9.17/x64/lib/python3.9/site-packages/PIL/Image.py", line 2432, in save
    save_handler(self, fp, filename)
  File "/opt/hostedtoolcache/Python/3.9.17/x64/lib/python3.9/site-packages/PIL/JpegImagePlugin.py", line 637, in _save
    raise ValueError(msg)
ValueError: cannot write empty image as JPEG

During handling of the above exception, another exception occurred:

Traceback (most recent call last):
  File "/home/runner/work/FortDaily-PVE_bot/FortDaily-PVE_bot/main.py", line 232, in <module>
    sending()
  File "/home/runner/work/FortDaily-PVE_bot/FortDaily-PVE_bot/main.py", line 201, in sending
    bot.send_photo(chat_id=channel_id, photo=page)
  File "/opt/hostedtoolcache/Python/3.9.17/x64/lib/python3.9/site-packages/telebot/__init__.py", line 1825, in send_photo
    apihelper.send_photo(
  File "/opt/hostedtoolcache/Python/3.9.17/x64/lib/python3.9/site-packages/telebot/apihelper.py", line 469, in send_photo
    files = {'photo': util.pil_image_to_file(photo)}
  File "/opt/hostedtoolcache/Python/3.9.17/x64/lib/python3.9/site-packages/telebot/service_utils.py", line 62, in pil_image_to_file
    image.convert('RGB').save(photoBuffer, extension, quality=quality)
  File "/opt/hostedtoolcache/Python/3.9.17/x64/lib/python3.9/site-packages/PIL/Image.py", line 2432, in save
    save_handler(self, fp, filename)
  File "/opt/hostedtoolcache/Python/3.9.17/x64/lib/python3.9/site-packages/PIL/JpegImagePlugin.py", line 637, in _save
    raise ValueError(msg)
ValueError: cannot write empty image as JPEG
00:30:03 - main - WARNING - <module>: 18 - ________________________________HELLO__________________________________
00:30:33 - main - WARNING - sending: 194 - A request to the Telegram API was unsuccessful. Error code: 400. Description: Bad Request: failed to send message #9 with the error message "PHOTO_INVALID_DIMENSIONS"
00:30:58 - main - ERROR - <module>: 234 - A request to the Telegram API was unsuccessful. Error code: 400. Description: Bad Request: failed to send message #9 with the error message "PHOTO_INVALID_DIMENSIONS"
Traceback (most recent call last):
  File "/home/runner/work/FortDaily-PVE_bot/FortDaily-PVE_bot/main.py", line 188, in sending
    bot.send_media_group(chat_id=channel_id, media=mediagroup)
  File "/opt/hostedtoolcache/Python/3.9.17/x64/lib/python3.9/site-packages/telebot/__init__.py", line 2523, in send_media_group
    result = apihelper.send_media_group(
  File "/opt/hostedtoolcache/Python/3.9.17/x64/lib/python3.9/site-packages/telebot/apihelper.py", line 516, in send_media_group
    return _make_request(
  File "/opt/hostedtoolcache/Python/3.9.17/x64/lib/python3.9/site-packages/telebot/apihelper.py", line 162, in _make_request
    json_result = _check_result(method_name, result)
  File "/opt/hostedtoolcache/Python/3.9.17/x64/lib/python3.9/site-packages/telebot/apihelper.py", line 189, in _check_result
    raise ApiTelegramException(method_name, result, result_json)
telebot.apihelper.ApiTelegramException: A request to the Telegram API was unsuccessful. Error code: 400. Description: Bad Request: failed to send message #9 with the error message "PHOTO_INVALID_DIMENSIONS"

During handling of the above exception, another exception occurred:

Traceback (most recent call last):
  File "/home/runner/work/FortDaily-PVE_bot/FortDaily-PVE_bot/main.py", line 232, in <module>
    sending()
  File "/home/runner/work/FortDaily-PVE_bot/FortDaily-PVE_bot/main.py", line 198, in sending
    bot.send_media_group(chat_id=channel_id, media=mediagroup)
  File "/opt/hostedtoolcache/Python/3.9.17/x64/lib/python3.9/site-packages/telebot/__init__.py", line 2523, in send_media_group
    result = apihelper.send_media_group(
  File "/opt/hostedtoolcache/Python/3.9.17/x64/lib/python3.9/site-packages/telebot/apihelper.py", line 516, in send_media_group
    return _make_request(
  File "/opt/hostedtoolcache/Python/3.9.17/x64/lib/python3.9/site-packages/telebot/apihelper.py", line 162, in _make_request
    json_result = _check_result(method_name, result)
  File "/opt/hostedtoolcache/Python/3.9.17/x64/lib/python3.9/site-packages/telebot/apihelper.py", line 189, in _check_result
    raise ApiTelegramException(method_name, result, result_json)
telebot.apihelper.ApiTelegramException: A request to the Telegram API was unsuccessful. Error code: 400. Description: Bad Request: failed to send message #9 with the error message "PHOTO_INVALID_DIMENSIONS"
00:29:57 - main - WARNING - <module>: 18 - ________________________________HELLO__________________________________
00:30:31 - main - WARNING - sending: 194 - A request to the Telegram API was unsuccessful. Error code: 400. Description: Bad Request: PHOTO_INVALID_DIMENSIONS
00:31:03 - main - ERROR - <module>: 234 - A request to the Telegram API was unsuccessful. Error code: 400. Description: Bad Request: PHOTO_INVALID_DIMENSIONS
Traceback (most recent call last):
  File "/home/runner/work/FortDaily-PVE_bot/FortDaily-PVE_bot/main.py", line 191, in sending
    bot.send_photo(chat_id=channel_id, photo=page)
  File "/opt/hostedtoolcache/Python/3.9.17/x64/lib/python3.9/site-packages/telebot/__init__.py", line 1825, in send_photo
    apihelper.send_photo(
  File "/opt/hostedtoolcache/Python/3.9.17/x64/lib/python3.9/site-packages/telebot/apihelper.py", line 494, in send_photo
    return _make_request(token, method_url, params=payload, files=files, method='post')
  File "/opt/hostedtoolcache/Python/3.9.17/x64/lib/python3.9/site-packages/telebot/apihelper.py", line 162, in _make_request
    json_result = _check_result(method_name, result)
  File "/opt/hostedtoolcache/Python/3.9.17/x64/lib/python3.9/site-packages/telebot/apihelper.py", line 189, in _check_result
    raise ApiTelegramException(method_name, result, result_json)
telebot.apihelper.ApiTelegramException: A request to the Telegram API was unsuccessful. Error code: 400. Description: Bad Request: PHOTO_INVALID_DIMENSIONS

During handling of the above exception, another exception occurred:

Traceback (most recent call last):
  File "/home/runner/work/FortDaily-PVE_bot/FortDaily-PVE_bot/main.py", line 232, in <module>
    sending()
  File "/home/runner/work/FortDaily-PVE_bot/FortDaily-PVE_bot/main.py", line 201, in sending
    bot.send_photo(chat_id=channel_id, photo=page)
  File "/opt/hostedtoolcache/Python/3.9.17/x64/lib/python3.9/site-packages/telebot/__init__.py", line 1825, in send_photo
    apihelper.send_photo(
  File "/opt/hostedtoolcache/Python/3.9.17/x64/lib/python3.9/site-packages/telebot/apihelper.py", line 494, in send_photo
    return _make_request(token, method_url, params=payload, files=files, method='post')
  File "/opt/hostedtoolcache/Python/3.9.17/x64/lib/python3.9/site-packages/telebot/apihelper.py", line 162, in _make_request
    json_result = _check_result(method_name, result)
  File "/opt/hostedtoolcache/Python/3.9.17/x64/lib/python3.9/site-packages/telebot/apihelper.py", line 189, in _check_result
    raise ApiTelegramException(method_name, result, result_json)
telebot.apihelper.ApiTelegramException: A request to the Telegram API was unsuccessful. Error code: 400. Description: Bad Request: PHOTO_INVALID_DIMENSIONS
